Workbook

Sheet Rx. Pr. Calc. with N2
C1: H2/Naphtha (mol. Basis) | D1: 1.5
C2: Naphtha (M. Wt.) | D2: 100
C3: N2 flow, SLPH | D3: 2
C4: Naphtha flow rate, g/hr | D4: 2
C6: H2 flow, g/hr | D6: =(D4/D2)*D1*2 -> 0.06
C7: H2 flow, SLPH | D7: =D11*22.4 -> 0.672
D9: moles/hr | E9: %
C10: Naphtha flow rate | D10: =D4/D2 -> 0.02 | E10: =D10/$D$13*100 -> 14.358974
C11: H2 flow | D11: =D10*D1 -> 0.03 | E11: =D11/$D$13*100 -> 21.538462
C12: N2 flow | D12: =D3/22.4 -> 0.089285714 | E12: =D12/$D$13*100 -> 64.102564
C13: Total | D13: =SUM(D10:D12) -> 0.13928571 | E13: =SUM(E10:E12) -> 100
D15: gms/hr | E15: %
C16: Naphtha flow rate | D16: =D4 -> 2 | E16: =D16/$D$19*100 -> 43.859649
C17: H2 flow | D17: =D6 -> 0.06 | E17: =D17/$D$19*100 -> 1.3157895
C18: N2 flow | D18: =D12*28 -> 2.5 | E18: =D18/$D$19*100 -> 54.824561
C19: Total | D19: =SUM(D16:D18) -> 4.56 | E19: =D19/$D$19*100 -> 100
C21: Total Pressure, barg | D21: 24 | E21: w/o N2
C22: H2 Partial Pressure, barg | D22: =D21*D11/SUM(D10:D11) -> 14.4
C23: Total Pressure, barg | D23: =D22/(E11/100) -> 66.857143 | E23: with N2

Sheet ETCA data with syn. feed
B1: Catalyst | C1: Athos 3 Cy1.6
C2: 6.05 | D2: g
B3: Feed | C3: 85 | D3: %w n-hexane
C4: 10 | D4: %w n-heptane
C5: 5 | D5: %w n-octane
C6: 0.66 | D6: g/ml
C7: 86.18 | D7: assumed MW
K11: indicative results (08/01/2026)
C12: Pressure | D12: T | E12: feed flow | F12: H2 flow | H12: H2/HC | I12: WHSV | K12: hexaan conversie | L12: hexaan crack | M12: heptaan crack | N12: octaan crack
D13: isothermal | E13: ml/min | F13: Nl/h | H13: mol/mol
B14: #RN1 | C14: 26 | D14: 220 | E14: 0.257 | F14: 4 | H14: =(F14/22.4)/(60*E14*$C$6/$C$7) -> 1.5121336 | I14: =E14*60*$C$6/$C$2 -> 1.6821818 | K14: 32.53 | L14: 5.7 | M14: 37.53 | N14: 80.13
B15: #RN2 | C15: 26 | D15: 200 | E15: 0.257 | F15: 4 | H15: =(F15/22.4)/(60*E15*$C$6/$C$7) -> 1.5121336 | I15: =E15*60*$C$6/$C$2 -> 1.6821818 | K15: 11.26 | L15: 2.22 | M15: 3.59 | N15: 31.67
B16: #RN3 | C16: 26 | D16: 210 | E16: 0.257 | F16: 4 | H16: =(F16/22.4)/(60*E16*$C$6/$C$7) -> 1.5121336 | I16: =E16*60*$C$6/$C$2 -> 1.6821818 | K16: 16.22 | L16: 1.94 | M16: 13.73 | N16: 55.23
B17: #RN4 | C17: 26 | D17: 230 | E17: 0.257 | F17: 4 | H17: =(F17/22.4)/(60*E17*$C$6/$C$7) -> 1.5121336 | I17: =E17*60*$C$6/$C$2 -> 1.6821818 | K17: 45.45 | L17: 3.4 | M17: 59.2 | N17: 88.8
B18: #RN5 | C18: 26 | D18: 190 | E18: 0.257 | F18: 4 | H18: =(F18/22.4)/(60*E18*$C$6/$C$7) -> 1.5121336 | I18: =E18*60*$C$6/$C$2 -> 1.6821818 | K18: 8.29 | L18: 1.59 | M18: -0.03 | N18: 18.95
B19: #RN6 | C19: 26 | D19: 220 | E19: 0.257 | F19: 3.18 | H19: =(F19/22.4)/(60*E19*$C$6/$C$7) -> 1.2021462 | I19: =E19*60*$C$6/$C$2 -> 1.6821818
B20: #RN7 | C20: 26 | D20: 200 | E20: 0.257 | F20: 3.18 | H20: =(F20/22.4)/(60*E20*$C$6/$C$7) -> 1.2021462 | I20: =E20*60*$C$6/$C$2 -> 1.6821818 | K20: 12.1 | L20: 1.83 | M20: 6.17 | N20: 37.81
B21: #RN8 | C21: 26 | D21: 210 | E21: 0.257 | F21: 3.18 | H21: =(F21/22.4)/(60*E21*$C$6/$C$7) -> 1.2021462 | I21: =E21*60*$C$6/$C$2 -> 1.6821818 | K21: 17.08 | L21: 1.94 | M21: 15.23 | N21: 57.51
B22: #RN9 | C22: 26 | D22: 230 | E22: 0.257 | F22: 3.18 | H22: =(F22/22.4)/(60*E22*$C$6/$C$7) -> 1.2021462 | I22: =E22*60*$C$6/$C$2 -> 1.6821818 | K22: 46.11 | L22: 3.48 | M22: 60.33 | N22: 87.93
B23: #RN10 | C23: 26 | D23: 190 | E23: 0.257 | F23: 3.18 | H23: =(F23/22.4)/(60*E23*$C$6/$C$7) -> 1.2021462 | I23: =E23*60*$C$6/$C$2 -> 1.6821818 | K23: 10.63 | L23: 1.92 | M23: 2.82 | N23: 23.03
B24: #RN11 | C24: 26 | D24: 180 | E24: 0.257 | F24: 3.18 | H24: =(F24/22.4)/(60*E24*$C$6/$C$7) -> 1.2021462 | I24: =E24*60*$C$6/$C$2 -> 1.6821818 | K24: 4.39 | L24: 1.34 | M24: -6.06 | N24: 4.13
B25: #RN12 | C25: 26 | D25: 220 | E25: =2*0.257 -> 0.514 | F25: =2*3.18 -> 6.36 | H25: =(F25/22.4)/(60*E25*$C$6/$C$7) -> 1.2021462 | I25: =E25*60*$C$6/$C$2 -> 3.3643636 | K25: 16.88 | L25: 1.75 | M25: 16.48 | N25: 56.06
B26: #RN13 | C26: 26 | D26: 240 | E26: =1.5*0.257 -> 0.3855 | F26: =1.5*3.18 -> 4.77 | H26: =(F26/22.4)/(60*E26*$C$6/$C$7) -> 1.2021462 | I26: =E26*60*$C$6/$C$2 -> 2.5232727 | K26: 45.52 | L26: 3.29 | M26: 60.17 | N26: 84.99
B27: #RN14 | C27: 15 | D27: 220 | E27: 0.257 | F27: 4 | H27: =(F27/22.4)/(60*E27*$C$6/$C$7) -> 1.5121336 | I27: =E27*60*$C$6/$C$2 -> 1.6821818 | K27: 39.58 | L27: 3.03 | M27: 53.01 | N27: 84.63
B28: #RN15 | C28: 15 | D28: 200 | E28: 0.257 | F28: 4 | H28: =(F28/22.4)/(60*E28*$C$6/$C$7) -> 1.5121336 | I28: =E28*60*$C$6/$C$2 -> 1.6821818 | K28: 15.71 | L28: 1.99 | M28: 12.42 | N28: 52.49
B29: #RN16 | C29: 15 | D29: 210 | E29: 0.257 | F29: 4 | H29: =(F29/22.4)/(60*E29*$C$6/$C$7) -> 1.5121336 | I29: =E29*60*$C$6/$C$2 -> 1.6821818 | K29: 21.52 | L29: 1.87 | M29: 24.38 | N29: 72.96
B30: #RN17 | C30: 15 | D30: 230 | E30: 0.257 | F30: 4 | H30: =(F30/22.4)/(60*E30*$C$6/$C$7) -> 1.5121336 | I30: =E30*60*$C$6/$C$2 -> 1.6821818 | K30: 53.54 | L30: 3.11 | M30: 71.77 | N30: 87.85
B31: #RN18 | C31: 15 | D31: 190 | E31: 0.257 | F31: 4 | H31: =(F31/22.4)/(60*E31*$C$6/$C$7) -> 1.5121336 | I31: =E31*60*$C$6/$C$2 -> 1.6821818 | K31: 12.02 | L31: 1.92 | M31: 5.11 | N31: 32.75
B32: #RN19 | C32: 15 | D32: 180 | E32: 0.257 | F32: =F31 -> 4 | H32: =(F32/22.4)/(60*E32*$C$6/$C$7) -> 1.5121336 | I32: =E32*60*$C$6/$C$2 -> 1.6821818 | K32: 4.89 | L32: 1.4 | M32: -5.92 | N32: 8.72
S34: In ETCA, a total of 19 conditions were evaluated using the synthetic feed and catalyst system. For the chemical validation run in the ILS unit at STC B, it was agreed with stakeholders that the first five of these conditions (highlighted in grey) would be replicated at STCB. These will be executed in the order of increasing temperature from 190°C to 230°C, with 10°C increments, rather than following the sequence used in ETCA. In addition, a low pressure condition at 15 bar (ETCA condition RN 14) is also included. This low pressure condition is particularly important because ETCA results show a significant increase in conversion when operating pressure is reduced. Including this condition in the validation plan will allow us to determine whether the ILS unit exhibits a similar change in performance under the same pressure shift. In ETCA, each condition was held for approximately 6 hours, during which about four GC data points were collected. The stable points were then selected and averaged to generate the reported data. In the case of the ILS unit, achieving stabilization within 6 hours is unlikely due to system dynamics. Therefore, it was agreed that each condition will instead be run for approximately 24–30 hours to ensure stable data before moving on to the next condition
C35: ETCA
C37: Temperature | D37: Temperature | E37: 1/T | F37: Rate Constant
C38: degC | D38: K | E38: K-1 | F38: 1st order
C39: =D18 -> 190 | D39: =C39+273 -> 463 | E39: =1/D39 -> 0.0021598272 | F39: =-LN((100-K18)/100)*I14 -> 0.14557393
C40: =D15 -> 200 | D40: =C40+273 -> 473 | E40: =1/D40 -> 0.0021141649 | F40: =-LN((100-K15)/100)*I15 -> 0.2009525
C41: =D16 -> 210 | D41: =C41+273 -> 483 | E41: =1/D41 -> 0.0020703934 | F41: =-LN((100-K16)/100)*I16 -> 0.29770559
C42: =D14 -> 220 | D42: =C42+273 -> 493 | E42: =1/D42 -> 0.0020283976 | F42: =-LN((100-K14)/100)*I17 -> 0.6619169
C43: =D17 -> 230 | D43: =C43+273 -> 503 | E43: =1/D43 -> 0.0019880716 | F43: =-LN((100-K17)/100)*I18 -> 1.0194905
E49: E/R | F49: 1697
E50: R2 | F50: 0.97
...

Sheet Feed Specs. for ATHOS-3

Sheet Catalyst Activation Step
A1: Steps | B1: Start Temperature | C1: Target Temperature | D1: Ramp Rate, oC/hr | E1: Holding, hrs | F1: N2 flow, NLPH | G1: H2 flow, NLPH | H1: Pressure, barg | I1: Remarks | L1: Step | M1: Time, hrs | N1: Cumulative Time, hrs | O1: Temperature, oC | P1: N2/H2, barg
A2: 1 | B2: 25 | C2: =B2 -> 25 | D2: 0 | E2: 1 | H2: 15 | L2: 1 | M2: =(C2-B2) -> 0 | N2: 0 | O2: =B2 -> 25 | P2: =H2 -> 15
A3: =A2+1 -> 2 | B3: 25 | C3: 180 | D3: 30 | E3: 0.5 | H3: 15 | M3: =E2 -> 1 | N3: =M3+N2 -> 1 | O3: =C2 -> 25 | P3: =H2 -> 15
A4: =A3+1 -> 3 | B4: =C3 -> 180 | C4: 220 | D4: 30 | E4: 0.5 | H4: 15 | L4: 2 | M4: =(C3-B3)/D3 -> 5.1666667 | N4: =M4+N3 -> 6.1666667 | O4: =C3 -> 180 | P4: =H3 -> 15
A5: =A4+1 -> 4 | B5: 220 | C5: 260 | D5: 30 | E5: 2 | H5: 15 | M5: =E3 -> 0.5 | N5: =M5+N4 -> 6.6666667 | O5: =C3 -> 180 | P5: =H3 -> 15
A6: =A5+1 -> 5 | B6: 260 | C6: 160 | D6: 30 | E6: 0.5 | H6: 15 | L6: 3 | M6: =(C4-B4)/D4 -> 1.3333333 | N6: =M6+N5 -> 8 | O6: =C4 -> 220 | P6: =H4 -> 15
A7: =A6+1 -> 6 | B7: 160 | C7: 160 | D7: 0 | E7: 1 | H7: 25 | I7: Switch to H2 gas and increase Pressure to 25 barg | M7: =E4 -> 0.5 | N7: =M7+N6 -> 8.5 | O7: =C4 -> 220 | P7: =H4 -> 15
A8: =A7+1 -> 7 | B8: 160 | C8: 260 | D8: 30 | E8: 6 | H8: 25 | L8: 4 | M8: =(C5-B5)/D5 -> 1.3333333 | N8: =M8+N7 -> 9.8333333 | O8: =C5 -> 260 | P8: =H5 -> 15
A9: =A8+1 -> 8 | B9: 260 | C9: 190 | D9: 30 | E9: 0.5 | H9: 25 | M9: =E5 -> 2 | N9: =M9+N8 -> 11.833333 | O9: =C5 -> 260 | P9: =H5 -> 15
A10: =A9+1 -> 9 | B10: 190 | C10: 190 | D10: 0 | E10: 1 | H10: 25 | I10: Adjust H2 flow and introduce liquid feed as per condition 1 | L10: 5 | M10: =(B6-C6)/D6 -> 3.3333333 | N10: =M10+N9 -> 15.166667 | O10: =C6 -> 160 | P10: =H6 -> 15
M11: =E6 -> 0.5 | N11: =M11+N10 -> 15.666667 | O11: =C6 -> 160 | P11: =H6 -> 15
L12: 6 | M12: =(C7-B7) -> 0 | N12: =M12+N11 -> 15.666667 | O12: 160 | P12: =H7 -> 25 | Q12: =I7 -> Switch to H2 gas and increase Pressure to 25 barg
M13: =E7 -> 1 | N13: =M13+N12 -> 16.666667 | O13: =C7 -> 160 | P13: =H7 -> 25
L14: 7 | M14: =(C8-B8)/D8 -> 3.3333333 | N14: =M14+N13 -> 20 | O14: =C8 -> 260 | P14: =H8 -> 25
M15: =E8 -> 6 | N15: =M15+N14 -> 26 | O15: =C8 -> 260 | P15: =H8 -> 25
L16: 8 | M16: =(B9-C9)/D9 -> 2.3333333 | N16: =M16+N15 -> 28.333333 | O16: =C9 -> 190 | P16: =H9 -> 25
M17: =E9 -> 0.5 | N17: =M17+N16 -> 28.833333 | O17: =C9 -> 190 | P17: =H9 -> 25
L18: 9 | M18: =(C10-B10) -> 0 | N18: =M18+N17 -> 28.833333 | O18: =C10 -> 190 | P18: =H10 -> 25
M19: =E10 -> 1 | N19: =M19+N18 -> 29.833333 | O19: =C10 -> 190 | P19: =H10 -> 25 | Q19: Adjust H2 flow and introduce liquid feed as per condition 1

Sheet Catalyst Loading Details
T5: Zones | U5: Reactor
O6: Reactor ID | P6: mm | Q6: 4.4 | U6: 1 | V6: 2 | W6: 6
G7: Empty space | O7: Isothermal zone height | P7: mm | Q7: 300 | T7: Preheating Zone, mm | U7: =875-U8-U9 -> 421 | V7: =875-V8-V9 -> 419 | W7: =875-W8-W9 -> 420
O8: Isothermal zone volume | P8: ml | Q8: =(22/28)*(Q6*Q6)*Q7/1000 -> 4.5634286 | T8: Catalyst Bed Zone, mm | U8: 154 | V8: 156 | W8: 155
G9: Preheating Zone SiC, 0.8 mm | O9: Catalyst volume | P9: ml | Q9: 2 | T9: Post Heating Zone, mm | U9: 300 | V9: 300 | W9: 300
G13: ATHOS-3, CY 1.6 (1.9ml) + SiC 50 microns (1.9 ml) equally divided into 10 portions
G19: Post Heating Zone SiC, 0.8 mm
AE57: =AE56*40 -> 0

Sheet Exp. Plan for Validation Run
A2: Objective | B2: Chemically validate the ILS‑8 reactor unit for the isomerization application using ETCA‑equivalent feed, catalyst, and operating conditions and also evaluate tube to tube repeatability across the identified reactors.
A4: Catalyst Loading Plan | B4: Units | C4: Block 1 | G4: Block 2
A5: Reactor | B5: -- | C5: 1 | D5: 2 | E5: 3 | F5: 4 | G5: 5 | H5: 6 | I5: 7 | J5: 8
A6: Catalyst | B6: -- | C6: ATHOS-3 | D6: ATHOS-3 | E6: X | F6: X | G6: SiC-INERT | H6: ATHOS-3 | I6: X | J6: X
A7: Shape & Size | B7: mm | C7: CY 1.6 | D7: CY 1.6 | E7: X | F7: X | G7: 0.8 mm | H7: CY 1.6 | I7: X | J7: X
A8: Catalyst volume | B8: ml | C8: 1.9 | D8: 1.9 | E8: X | F8: X | G8: 1.9 | H8: 1.9 | I8: X | J8: X
A9: Catalyst CBD (as-is) | B9: g/ml | C9: 0.654 | D9: 0.654 | E9: X | F9: X | G9: 1.7 | H9: 0.654 | I9: X | J9: X
A10: Catalyst amount | B10: gms | C10: =C8*C9 -> 1.2426 | D10: =D8*D9 -> 1.2426 | E10: X | F10: X | G10: =G8*G9 -> 3.23 | H10: =H8*H9 -> 1.2426 | I10: X | J10: X
A12: Op.Conditions | B12: Units | C12: 1 | D12: 2 | E12: 3 | F12: 4 | G12: 5 | H12: 6
A13: Pressure | B13: barg | C13: 26 | D13: 26 | E13: 26 | F13: 26 | G13: 26 | H13: 15
A14: Temperature | B14: oC | C14: 190 | D14: 200 | E14: 210 | F14: 220 | G14: 230 | H14: 230
A15: WHSV | B15: h-1 | C15: 1.68 | D15: 1.68 | E15: 1.68 | F15: 1.68 | G15: 1.68 | H15: 1.68
A16: H2/Naphtha | B16: mol.basis | C16: 1.51 | D16: 1.51 | E16: 1.51 | F16: 1.51 | G16: 1.51 | H16: 1.51
A17: Duration | B17: hrs | C17: 24 to 36 | D17: 24 to 36 | E17: 24 to 36 | F17: 24 to 36 | G17: 24 to 36 | H17: 24 to 36
A19: Feed molecular weight | C19: 88.5 | D19: from offline DHA
A20: Pressure | B20: barg | D20: Constant for R1, R2, R5 and R6 across all six conditions
A21: Temperature | B21: oC | D21: Temperature for R1, R2, R5, and R6 remain constant within each condition; when the condition changes, all reactor temperatures are to be adjusted accordingly
A22: Naphtha flow | B22: gms/hr | C22: =C15*C9*C8*0.965 -> 2.0145031 | D22: Constant for R1, R2, and R6 across all six conditions; R5 to be operated under gas and liquid feed
A23: H2 flow | B23: gms/hr | C23: =(C22/C19)*(C16*2) -> 0.068743496 | D23: Constant for R1, R2, R5 and R6 across all six conditions
A24: N2 dilution flow | B24: NLPH | C24: 2 | D24: Constant for R1, R2, R5 and R6 across all six conditions
A26: Note
A27: Identical conditions for all reactors loaded with catalyst
A28: A reactor loaded with inert material will operate under the same conditions as a catalyst‑loaded reactor, except that no naphtha feed is introduced.
A52: H2 flow rate | B52: NLPH

Sheet Synthetic Feed_Calc
J1: Synthetic Feed Blend Composition (ETCA) | AJ1: APR 06, 2026 - 04:53:53
B2: Target Blend Feed, gms | D2: 50 | E2: B00009774001 | F2: also check for "S" and "N" and " moisture content analysis" | Y2: Synthetic Feed b lend (STCB), offline | AJ2: Synthetic Feed blend (STCB), online from R5
L3: SAMPLE_ID | M3: Alkane mix feed | V3: COMPONENT | W3: %WGT | Y3: CARBON# | Z3: Paraffin | AA3: I-Paraffins | AB3: Aromatics | AC3: Naphthenes | AD3: Olefins | AE3: Oxygenates | AF3: Plus | AG3: TOTAL | AJ3: CARBON# | AK3: Paraffin | AL3: I-Paraffins | AM3: Aromatics | AN3: Naphthenes | AO3: Olefins | AP3: Oxygenates | AQ3: Plus | AR3: TOTAL
A4: S.No. | B4: Solvents | C4: Purity, wt% | D4: Blend Composition, wt% | E4: Blend Quantity, gms | F4: Blend Composition (Estimated), wt% | G4: Blend Composition (ETCA), wt% | V4: 2-Methylpentane | W4: 0.019 | Y4: 1 | Z4: -- | AA4: -- | AB4: -- | AC4: -- | AD4: -- | AE4: -- | AF4: -- | AG4: 0 | AJ4: 1 | AK4: -- | AL4: -- | AM4: -- | AN4: -- | AO4: -- | AP4: -- | AQ4: -- | AR4: 0
A5: 1 | B5: n-hexane | C5: 95 | D5: 85 | E5: =$D$2*(D5/100)*(C5/100) -> 40.375 | F5: =E5/$D$2*100 -> 80.75 | G5: 83.42 | V5: 3-Methylpentane | W5: 0.304 | Y5: 2 | Z5: -- | AA5: -- | AB5: -- | AC5: -- | AD5: -- | AE5: -- | AF5: -- | AG5: 0 | AJ5: 2 | AK5: -- | AL5: -- | AM5: -- | AN5: -- | AO5: -- | AP5: -- | AQ5: -- | AR5: 0
A6: 2 | B6: n-heptane | C6: 99 | D6: 10 | E6: =$D$2*(D6/100)*(C6/100) -> 4.95 | F6: =E6/$D$2*100 -> 9.9 | G6: 10.37 | J6: SUMMARY_BY_CARBON_TABULAR(%WGT) | V6: n-Hexane | W6: 83.429 | Y6: 3 | Z6: -- | AA6: -- | AB6: -- | AC6: -- | AD6: -- | AE6: -- | AF6: -- | AG6: 0 | AJ6: 3 | AK6: -- | AL6: -- | AM6: -- | AN6: -- | AO6: -- | AP6: -- | AQ6: -- | AR6: 0
A7: 3 | B7: n-Octane | C7: 99 | D7: 5 | E7: =$D$2*(D7/100)*(C7/100) -> 2.475 | F7: =E7/$D$2*100 -> 4.95 | G7: 5.3 | V7: 2,2-Dimethylpentane | W7: 0.511 | Y7: 4 | Z7: -- | AA7: -- | AB7: -- | AC7: -- | AD7: -- | AE7: -- | AF7: -- | AG7: 0 | AJ7: 4 | AK7: 0.002040731 | AL7: -- | AM7: -- | AN7: -- | AO7: -- | AP7: -- | AQ7: -- | AR7: 0.002040731
D8: =SUM(D5:D7) -> 100 | K8: CARBON# | L8: Paraffin | M8: I-Paraffins | N8: Aromatics | O8: Naphthenes | P8: Olefins | Q8: Oxygenates | R8: Plus | S8: TOTAL | V8: n-Heptane | W8: 10.368 | Y8: 5 | Z8: -- | AA8: -- | AB8: -- | AC8: -- | AD8: -- | AE8: -- | AF8: -- | AG8: 0 | AJ8: 5 | AK8: 0.00703464 | AL8: 0.005083027 | AM8: -- | AN8: 0.00126478 | AO8: -- | AP8: -- | AQ8: -- | AR8: 0.013382448
K9: 1 | L9: -- | M9: -- | N9: -- | O9: -- | P9: -- | Q9: -- | R9: -- | S9: 0 | V9: 1c,2c,3-Trimethylcyclopentane | W9: 0.006 | Y9: 6 | Z9: 82.194557 | AA9: 0.57953048 | AB9: -- | AC9: 1.5385151 | AD9: -- | AE9: -- | AF9: -- | AG9: 84.312599 | AJ9: 6 | AK9: 86.275978 | AL9: 0.42940185 | AM9: -- | AN9: 0.57664788 | AO9: -- | AP9: -- | AQ9: -- | AR9: 87.282028
K10: 2 | L10: -- | M10: -- | N10: -- | O10: -- | P10: -- | Q10: -- | R10: -- | S10: 0 | V10: n-Octane | W10: 5.363 | Y10: 7 | Z10: 10.286925 | AA10: -- | AB10: -- | AC10: 0.020310303 | AD10: -- | AE10: -- | AF10: -- | AG10: 10.307236 | AJ10: 7 | AK10: 9.4333334 | AL10: 0.010966498 | AM10: -- | AN10: 0.004715566 | AO10: -- | AP10: -- | AQ10: -- | AR10: 9.4490156
K11: 3 | L11: -- | M11: -- | N11: -- | O11: -- | P11: -- | Q11: -- | R11: -- | S11: 0 | Y11: 8 | Z11: 5.3801694 | AA11: -- | AB11: -- | AC11: -- | AD11: -- | AE11: -- | AF11: -- | AG11: 5.3801694 | AJ11: 8 | AK11: 3.0644438 | AL11: 0.029610613 | AM11: -- | AN11: 0.048574667 | AO11: -- | AP11: -- | AQ11: -- | AR11: 3.1426291
K12: 4 | L12: -- | M12: -- | N12: -- | O12: -- | P12: -- | Q12: -- | R12: -- | S12: 0 | Y12: 9 | Z12: -- | AA12: -- | AB12: -- | AC12: -- | AD12: -- | AE12: -- | AF12: -- | AG12: 0 | AJ12: 9 | AK12: 0.009293201 | AL12: 0.007923766 | AM12: 0.001734306 | AN12: 0.0022839 | AO12: -- | AP12: -- | AQ12: -- | AR12: 0.021235174
D13: Synthetic Feed Blend Composition, wt% | E13: STCB | G13: ETCA | K13: 5 | L13: -- | M13: -- | N13: -- | O13: -- | P13: -- | Q13: -- | R13: -- | S13: 0 | Y13: 10 | Z13: -- | AA13: -- | AB13: -- | AC13: -- | AD13: -- | AE13: -- | AF13: -- | AG13: 0 | AJ13: 10 | AK13: 0.008122366 | AL13: 0.005322486 | AM13: 0.002272646 | AN13: 0.001946052 | AO13: -- | AP13: -- | AQ13: -- | AR13: 0.01766355
D14: Molecules | E14: Offline | F14: Online | K14: 6 | L14: 83.429 | M14: 0.322 | N14: -- | O14: -- | P14: -- | Q14: -- | R14: -- | S14: =SUM(L14:O14) -> 83.751 | Y14: 11 | Z14: -- | AA14: -- | AB14: -- | AC14: -- | AD14: -- | AE14: -- | AF14: -- | AG14: 0 | AJ14: 11 | AK14: 0.00554406 | AL14: 0.008197479 | AM14: 0.00588339 | AN14: -- | AO14: -- | AP14: -- | AQ14: -- | AR14: 0.019624928 | AV14: Big Batch (off line analysis)
D15: 2-Methylpentane (C6) | G15: 0.019 | K15: 7 | L15: 10.368 | M15: 0.511 | N15: -- | O15: -- | P15: -- | Q15: -- | R15: -- | S15: =SUM(L15:O15) -> 10.879 | Y15: 12 | Z15: -- | AA15: -- | AB15: -- | AC15: -- | AD15: -- | AE15: -- | AF15: -- | AG15: 0 | AJ15: 12 | AK15: 0.00175657 | AL15: -- | AM15: 0.004322175 | AN15: -- | AO15: -- | AP15: -- | AQ15: -- | AR15: 0.006078744
D16: 3-Methylpentane (C6) | E16: 0.57953048 | G16: 0.304 | K16: 8 | L16: 5.363 | M16: -- | N16: -- | O16: 0.006 | P16: -- | Q16: -- | R16: -- | S16: =SUM(L16:O16) -> 5.369 | Y16: 13 | Z16: -- | AA16: -- | AB16: -- | AC16: -- | AD16: -- | AE16: -- | AF16: -- | AG16: 0 | AJ16: 13 | AK16: -- | AL16: -- | AM16: -- | AN16: -- | AO16: -- | AP16: -- | AQ16: -- | AR16: 0
D17: Methyl cyclopentane (C6) | E17: 1.5385151 | F17: 0.58100563 | K17: 9 | L17: -- | M17: -- | N17: -- | O17: -- | P17: -- | Q17: -- | R17: -- | S17: =SUM(L17:O17) -> 0 | Y17: 14 | Z17: -- | AA17: -- | AB17: -- | AC17: -- | AD17: -- | AE17: -- | AF17: -- | AG17: 0 | AJ17: 14 | AK17: -- | AL17: -- | AM17: -- | AN17: -- | AO17: -- | AP17: -- | AQ17: -- | AR17: 0
D18: n-hexane (C6) | E18: 82.194557 | F18: 86.275978 | G18: 83.429 | K18: 10 | L18: -- | M18: -- | N18: -- | O18: -- | P18: -- | Q18: -- | R18: -- | S18: =SUM(L18:O18) -> 0 | Y18: 15 | Z18: -- | AA18: -- | AB18: -- | AC18: -- | AD18: -- | AE18: -- | AF18: -- | AG18: 0 | AJ18: 15 | AK18: -- | AL18: -- | AM18: -- | AN18: -- | AO18: -- | AP18: -- | AQ18: -- | AR18: 0
D19: 2,2-Dimethylpentane (C7) | G19: 0.511 | K19: 11 | L19: -- | M19: -- | N19: -- | O19: -- | P19: -- | Q19: -- | R19: -- | S19: =SUM(L19:O19) -> 0
D20: 1c,2-Dimethylcyclopentane (C7) | K20: 12 | L20: -- | M20: -- | N20: -- | O20: -- | P20: -- | Q20: -- | R20: -- | S20: =SUM(L20:O20) -> 0 | Y20: TOTAL | Z20: 97.861656 | AA20: 0.57953048 | AB20: 0 | AC20: 1.5588254 | AD20: 0 | AE20: 0 | AF20: 0 | AG20: 100.00001 | AJ20: TOTAL | AK20: 98.807556 | AL20: 0.49650571 | AM20: 0.014212515 | AN20: 0.63543278 | AO20: 0 | AP20: 0 | AQ20: 0 | AR20: 99.953697
D21: n-heptane (C7) | E21: 10.286925 | F21: 9.4722185 | G21: 10.368 | K21: 13 | L21: -- | M21: -- | N21: -- | O21: -- | P21: -- | Q21: -- | R21: -- | S21: 0 | AF21: UNKNOWNS | AG21: 0 | AQ21: UNKNOWNS | AR21: 0.046287667
D22: 1c,2-Dimethylcyclopentane (C7) | E22: 0.020310303 | K22: 14 | L22: -- | M22: -- | N22: -- | O22: -- | P22: -- | Q22: -- | R22: -- | S22: 0 | AF22: GRAND_TOTAL | AG22: 100.00001 | AQ22: GRAND_TOTAL | AR22: 99.999985
D23: 1c,2c,3-Trimethylcyclopentane (C7) | G23: 0.006 | K23: 15 | L23: -- | M23: -- | N23: -- | O23: -- | P23: -- | Q23: -- | R23: -- | S23: 0
D24: n-octane (C8) | E24: 5.3801694 | F24: 3.2154758 | G24: 5.363
D25: Total | E25: =SUM(E15:E24) -> 100.00001 | F25: =SUM(F16:F24) -> 99.544678 | G25: =SUM(G15:G24) -> 100 | K25: TOTAL | L25: =SUM(L14:L16) -> 99.16 | M25: =SUM(M14:M16) -> 0.833 | N25: =SUM(N14:N16) -> 0 | O25: =SUM(O14:O16) -> 0.006 | P25: 0 | Q25: 0 | R25: 0 | S25: 100 | AJ25: APR 05, 2026 - 19:50:50
R26: UNKNOWNS | S26: 0 | AJ26: Synthetic Feed blend (STCB), online from R5
R27: GRAND_TOTAL | S27: 100 | AJ27: CARBON# | AK27: Paraffin | AL27: I-Paraffins | AM27: Aromatics | AN27: Naphthenes | AO27: Olefins | AP27: Oxygenates | AQ27: Plus | AR27: TOTAL
AJ28: 1 | AK28: -- | AL28: -- | AM28: -- | AN28: -- | AO28: -- | AP28: -- | AQ28: -- | AR28: 0
AJ29: 2 | AK29: -- | AL29: -- | AM29: -- | AN29: -- | AO29: -- | AP29: -- | AQ29: -- | AR29: 0
AJ30: 3 | AK30: -- | AL30: -- | AM30: -- | AN30: -- | AO30: -- | AP30: -- | AQ30: -- | AR30: 0
AJ31: 4 | AK31: 0.002012269 | AL31: 0.000497388 | AM31: -- | AN31: -- | AO31: -- | AP31: -- | AQ31: -- | AR31: 0.002509656
AJ32: 5 | AK32: 0.006954285 | AL32: 0.005316882 | AM32: -- | AN32: 0.001348769 | AO32: -- | AP32: -- | AQ32: -- | AR32: 0.013619935
AJ33: 6 | AK33: 86.080444 | AL33: 0.42624071 | AM33: -- | AN33: 0.58100563 | AO33: -- | AP33: -- | AQ33: -- | AR33: 87.087692
AJ34: 7 | AK34: 9.4722185 | AL34: 0.010982258 | AM34: -- | AN34: 0.004822898 | AO34: -- | AP34: -- | AQ34: -- | AR34: 9.4880238
E35: Moisture content, ppmw | F35: <100 | G35: actual value is below 30 ppm | AJ35: 8 | AK35: 3.2154758 | AL35: 0.030950319 | AM35: -- | AN35: 0.049831167 | AO35: -- | AP35: -- | AQ35: -- | AR35: 3.2962573
E36: Total Sulfur, ppmw | F36: <2.5 | AJ36: 9 | AK36: 0.011423086 | AL36: 0.009861145 | AM36: 0.001813711 | AN36: 0.002859483 | AO36: -- | AP36: -- | AQ36: -- | AR36: 0.025957424
E37: Total Nitrogen, ppmw | F37: <2.5 | AJ37: 10 | AK37: 0.008134374 | AL37: 0.005598063 | AM37: 0.002172304 | AN37: 0.002434537 | AO37: -- | AP37: -- | AQ37: -- | AR37: 0.018339278
E38: RON (Estimated) | F38: 23 | AJ38: 11 | AK38: 0.004806483 | AL38: 0.007187498 | AM38: 0.003648059 | AN38: -- | AO38: -- | AP38: -- | AQ38: -- | AR38: 0.01564204
AJ39: 12 | AK39: 0.001373788 | AL39: -- | AM39: 0.003038012 | AN39: -- | AO39: -- | AP39: -- | AQ39: -- | AR39: 0.0044118
AJ40: 13 | AK40: -- | AL40: -- | AM40: -- | AN40: -- | AO40: -- | AP40: -- | AQ40: -- | AR40: 0
...

Sheet N2 FLOW Callibration
D1: N2 Dilution FIC calibration
C3: Set Point Value(mln/hr) | E3: Defender Value(ml/min) | Q3: Average, ml/min | R3: Average, ml/hr | W3: =2000*1.2647+33.268 -> 2562.668 | AF3: =2000*1.2611+83.216 -> 2605.416
B4: Reactor Block 1
E5: 1 | F5: 2 | G5: 3 | H5: 4 | I5: 5 | J5: 6 | K5: 7 | L5: 8 | M5: 9 | N5: 10 | O5: Average
B6: 10i1FIC04 | C6: 1000 | E6: 21.506 | F6: 21.63 | G6: 21.51 | H6: 21.475 | I6: 21.642 | J6: 21.587 | K6: 21.601 | L6: 21.626 | M6: 21.664 | N6: 21.688 | O6: 21.592 | Q6: =AVERAGE(E6:O6) -> 21.592818 | R6: =Q6*60 -> 1295.5691
C7: 2000 | E7: 42.784 | F7: 42.921 | G7: 42.819 | H7: 42.667 | I7: 42.81 | J7: 42.618 | K7: 42.78 | L7: 42.743 | M7: 42.644 | N7: 42.729 | O7: 42.751 | Q7: =AVERAGE(E7:O7) -> 42.751455 | R7: =Q7*60 -> 2565.0873
C8: 2500 | E8: 53.421 | F8: 53.385 | G8: 53.344 | H8: 53.31 | I8: 53.299 | J8: 53.302 | K8: 53.273 | L8: 53.31 | M8: 53.364 | N8: 53.294 | O8: 53.33 | Q8: =AVERAGE(E8:O8) -> 53.330182 | R8: =Q8*60 -> 3199.8109
C9: 3000 | E9: 63.75 | F9: 63.729 | G9: 63.662 | H9: 63.713 | I9: 63.723 | J9: 63.532 | K9: 63.672 | L9: 63.75 | M9: 63.737 | N9: 63.83 | O9: 63.709 | Q9: =AVERAGE(E9:O9) -> 63.709727 | R9: =Q9*60 -> 3822.5836
B11: 10i1FIC03 | C11: 1000 | E11: 22.424 | F11: 22.426 | G11: 22.4 | H11: 22.426 | I11: 22.412 | J11: 22.403 | K11: 22.355 | L11: 22.395 | M11: 22.399 | N11: 22.426 | O11: 22.406 | Q11: =AVERAGE(E11:O11) -> 22.406545 | R11: =Q11*60 -> 1344.3927
C12: 2000 | E12: 43.399 | F12: 43.529 | G12: 43.431 | H12: 43.41 | I12: 43.371 | J12: 43.393 | K12: 43.439 | L12: 43.392 | M12: 43.43 | N12: 43.431 | O12: 43.422 | Q12: =AVERAGE(E12:O12) -> 43.422455 | R12: =Q12*60 -> 2605.3473
C13: 2500 | E13: 53.939 | F13: 54.002 | G13: 53.97 | H13: 54.001 | I13: 54.04 | J13: 54.002 | K13: 53.983 | L13: 53.827 | M13: 53.734 | N13: 53.821 | O13: 53.931 | Q13: =AVERAGE(E13:O13) -> 53.931818 | R13: =Q13*60 -> 3235.9091
C14: 3000 | E14: 64.576 | F14: 64.519 | G14: 64.466 | H14: 64.453 | I14: 64.41 | J14: 64.451 | K14: 64.424 | L14: 64.288 | M14: 64.52 | N14: 64.336 | O14: 64.444 | Q14: =AVERAGE(E14:O14) -> 64.444273 | R14: =Q14*60 -> 3866.6564
B16: 10i1FIC02 | C16: 1000 | E16: 21.949 | F16: 21.896 | G16: 21.979 | H16: 21.841 | I16: 21.91 | J16: 21.904 | K16: 21.891 | L16: 21.879 | M16: 21.881 | N16: 21.92 | O16: 21.905 | Q16: =AVERAGE(E16:O16) -> 21.905 | R16: =Q16*60 -> 1314.3
C17: 2000 | E17: 42.825 | F17: 42.736 | G17: 42.795 | H17: 42.583 | I17: 42.827 | J17: 42.613 | K17: 42.845 | L17: 42.892 | M17: 42.81 | N17: 43.025 | O17: 42.795 | Q17: =AVERAGE(E17:O17) -> 42.795091 | R17: =Q17*60 -> 2567.7055
C18: 2500 | E18: 53.179 | F18: 53.506 | G18: 53.141 | H18: 53.208 | I18: 53.172 | J18: 53.319 | K18: 53.685 | L18: 53.754 | M18: 53.723 | N18: 53.973 | O18: 53.466 | Q18: =AVERAGE(E18:O18) -> 53.466 | R18: =Q18*60 -> 3207.96
C19: 3000 | E19: 63.747 | F19: 63.761 | G19: 63.824 | H19: 63.82 | I19: 63.768 | J19: 63.646 | K19: 63.704 | L19: 63.698 | M19: 63.733 | N19: 63.786 | O19: 63.757 | Q19: =AVERAGE(E19:O19) -> 63.749455 | R19: =Q19*60 -> 3824.9673
B21: 10i1FIC01 | C21: 1000 | E21: 21.899 | F21: 21.868 | G21: 21.864 | H21: 21.89 | I21: 21.9 | J21: 21.899 | K21: 21.901 | L21: 21.941 | M21: 21.96 | N21: 21.961 | O21: 21.908 | Q21: =AVERAGE(E21:O21) -> 21.908273 | R21: =Q21*60 -> 1314.4964
C22: 2000 | E22: 42.932 | F22: 42.958 | G22: 42.934 | H22: 42.858 | I22: 43.018 | J22: 42.999 | K22: 42.97 | L22: 42.979 | M22: 42.937 | N22: 42.982 | O22: 42.956 | Q22: =AVERAGE(E22:O22) -> 42.956636 | R22: =Q22*60 -> 2577.3982
C23: 2500 | E23: 53.514 | F23: 53.645 | G23: 53.608 | H23: 54.467 | I23: 53.605 | J23: 53.629 | K23: 53.581 | L23: 53.618 | M23: 53.695 | N23: 53.48 | O23: 53.684 | Q23: =AVERAGE(E23:O23) -> 53.684182 | R23: =Q23*60 -> 3221.0509
C24: 3000 | E24: 64.25 | F24: 64.155 | G24: 64.23 | H24: 64.38 | I24: 64.28 | J24: 64.219 | K24: 64.247 | L24: 64.271 | M24: 64.169 | N24: 64.194 | O24: 64.239 | Q24: =AVERAGE(E24:O24) -> 64.239455 | R24: =Q24*60 -> 3854.3673
B26: Reactor Block 2
E27: 1 | F27: 2 | G27: 3 | H27: 4 | I27: 5 | J27: 6 | K27: 7 | L27: 8 | M27: 9 | N27: 10 | O27: Average
B28: 10i2FIC04 | C28: 1000 | E28: 21.765 | F28: 21.759 | G28: 21.753 | H28: 21.685 | I28: 21.741 | J28: 21.728 | K28: 21.738 | L28: 21.746 | M28: 21.767 | N28: 21.748 | O28: 21.743 | Q28: =AVERAGE(E28:O28) -> 21.743 | R28: =Q28*60 -> 1304.58
C29: 2000 | E29: 42.655 | F29: 42.657 | G29: 42.658 | H29: 42.683 | I29: 42.663 | J29: 42.522 | K29: 42.57 | L29: 42.711 | M29: 42.616 | N29: 42.595 | O29: 42.633 | Q29: =AVERAGE(E29:O29) -> 42.633 | R29: =Q29*60 -> 2557.98
C30: 2500 | E30: 53.986 | F30: 52.994 | G30: 53.065 | H30: 53 | I30: 52.943 | J30: 52.958 | K30: 53.015 | L30: 53.058 | M30: 53.036 | N30: 53.032 | O30: 53.108 | Q30: =AVERAGE(E30:O30) -> 53.108636 | R30: =Q30*60 -> 3186.5182
C31: 3000 | E31: 63.475 | F31: 63.392 | G31: 63.344 | H31: 63.364 | I31: 63.356 | J31: 63.392 | K31: 63.374 | L31: 63.553 | M31: 63.771 | N31: 63.694 | O31: 63.471 | Q31: =AVERAGE(E31:O31) -> 63.471455 | R31: =Q31*60 -> 3808.2873
B33: 10i2FIC03 | C33: 1000 | E33: 21.353 | F33: 21.351 | G33: 21.383 | H33: 21.351 | I33: 21.358 | J33: 21.36 | K33: 21.393 | L33: 21.412 | M33: 21.355 | N33: 21.4 | O33: 21.371 | Q33: =AVERAGE(E33:O33) -> 21.371545 | R33: =Q33*60 -> 1282.2927
C34: 2000 | E34: 42.442 | F34: 42.357 | G34: 42.306 | H34: 42.328 | I34: 42.353 | J34: 42.289 | K34: 42.334 | L34: 42.298 | M34: 42.296 | N34: 41.454 | O34: 42.245 | Q34: =AVERAGE(E34:O34) -> 42.245636 | R34: =Q34*60 -> 2534.7382
C35: 2500 | E35: 52.819 | F35: 52.865 | G35: 52.797 | H35: 52.773 | I35: 52.751 | J35: 52.849 | K35: 52.939 | L35: 52.728 | M35: 52.718 | N35: 52.715 | O35: 52.796 | Q35: =AVERAGE(E35:O35) -> 52.795455 | R35: =Q35*60 -> 3167.7273
C36: 3000 | E36: 63.011 | F36: 63.032 | G36: 62.999 | H36: 63.012 | I36: 63.105 | J36: 63.118 | K36: 63.112 | L36: 63.146 | M36: 63.047 | N36: 62.969 | O36: 63.055 | Q36: =AVERAGE(E36:O36) -> 63.055091 | R36: =Q36*60 -> 3783.3055
Y37: =2000*1.2525+52.826 -> 2557.826
B38: 10i2FIC02 | C38: 1000 | E38: 21.499 | F38: 21.523 | G38: 21.523 | H38: 21.53 | I38: 21.524 | J38: 21.537 | K38: 21.521 | L38: 21.536 | M38: 21.545 | N38: 21.534 | O38: 21.527 | Q38: =AVERAGE(E38:O38) -> 21.527182 | R38: =Q38*60 -> 1291.6309
C39: 2000 | E39: 42.437 | F39: 42.425 | G39: 42.4 | H39: 42.337 | I39: 42.397 | J39: 42.396 | K39: 42.382 | L39: 42.492 | M39: 42.436 | N39: 42.44 | O39: 42.414 | Q39: =AVERAGE(E39:O39) -> 42.414182 | R39: =Q39*60 -> 2544.8509
C40: 2500 | E40: 52.86 | F40: 52.781 | G40: 52.828 | H40: 52.838 | I40: 52.785 | J40: 52.805 | K40: 52.873 | L40: 52.82 | M40: 52.835 | N40: 52.826 | O40: 52.825 | Q40: =AVERAGE(E40:O40) -> 52.825091 | R40: =Q40*60 -> 3169.5055
C41: 3000 | E41: 63.282 | F41: 63.26 | G41: 63.314 | H41: 63.321 | I41: 63.309 | J41: 63.359 | K41: 63.357 | L41: 63.366 | M41: 63.384 | N41: 63.386 | O41: 63.333 | Q41: =AVERAGE(E41:O41) -> 63.333727 | R41: =Q41*60 -> 3800.0236
B43: 10i2FIC01 | C43: 1000 | E43: 21.096 | F43: 21.064 | G43: 21.069 | H43: 21.096 | I43: 21.096 | J43: 21.102 | K43: 21.093 | L43: 21.117 | M43: 21.087 | N43: 21.128 | O43: 21.094 | Q43: =AVERAGE(E43:O43) -> 21.094727 | R43: =Q43*60 -> 1265.6836
C44: 2000 | E44: 42.01 | F44: 42.005 | G44: 41.983 | H44: 41.995 | I44: 42.042 | J44: 42.03 | K44: 42.019 | L44: 42.0341 | M44: 42.074 | N44: 42.071 | O44: 42.026 | Q44: =AVERAGE(E44:O44) -> 42.026282 | R44: =Q44*60 -> 2521.5769
C45: 2500 | E45: 52.535 | F45: 52.476 | G45: 52.477 | H45: 52.473 | I45: 52.458 | J45: 52.45 | K45: 52.465 | L45: 52.434 | M45: 52.472 | N45: 52.493 | O45: 52.473 | Q45: =AVERAGE(E45:O45) -> 52.473273 | R45: =Q45*60 -> 3148.3964 | AJ45: =1.2521*2000+31.401 -> 2535.601
C46: 3000 | E46: 62.937 | F46: 62.974 | G46: 62.97 | H46: 62.986 | I46: 62.973 | J46: 62.971 | K46: 62.962 | L46: 62.947 | M46: 62.938 | N46: 62.969 | O46: 62.962 | Q46: =AVERAGE(E46:O46) -> 62.962636 | R46: =Q46*60 -> 3777.7582

Sheet GC Calibration Data
A2: 0 | H2: N2 | K2: H2
F3: ter # | G3: Batch # | H3: Conc (Vol%) | I3: Area | J3: RF | K3: Conc (Vol%) | L3: Area | M3: RF
F4: CAN-01 | G4: CFC2512006/30033552 | H4: 80.23 | I4: 442000000 | J4: 1.81317e-07 | K4: 19.77 | L4: 4556250 | M4: 4.3391e-06 | P4: 1.81317e-07 | Q4: =1.63/10000000 -> 1.63e-07
F5: CSL/16-17/SB3-207 | G5: CFC2512004/30035552 | H5: 60.13 | I5: 334000000 | J5: 1.80091e-07 | K5: 39.87 | L5: 9023977 | M5: 4.41823e-06 | P5: 1.80091e-07 | Q5: =1.74/1000000 -> 1.74e-06
F6: CSL/17-18/SB3/043 | G6: CFC2512005/30033552 | H6: 40.24 | I6: 229000000 | J6: 1.76049e-07 | K6: 59.76 | L6: 13285364 | M6: 4.49818e-06 | P6: 1.76049e-07 | Q6: =1.79/1000000 -> 1.79e-06
F7: CSL/19-20/SB3/HP05 | G7: CFC2512008/300333552 | H7: 20.43 | I7: 125000000 | J7: 1.63839e-07 | K7: 79.57 | L7: 17515766 | M7: 4.54276e-06
J8: 1.75324e-07 | M8: 4.44957e-06
J14: Inter/Extra polation | K14: =-0.0000000000244761948*K15^2 + 0.00000000584415609*K15 + 0.00000423201041 -> 4.3391031e-06 | L14: Determined from Co-Pilot
J15: H2 | K15: 20
J28: Inter/Extra polation | K28: =1.07154555E-13*K29^3 - 0.0000000000231369299*K29^2 + 0.00000000170314458*K29 + 0.000000137948036 -> 1.6361339e-07 | L28: Determined from Co-Pilot
J29: N2 | K29: 20

Sheet RF Factors (applied)
B3: H2 (RF) | C3: 4.54276e-06
B4: N2 (RF) | C4: 1.75809e-07

Sheet Feed
D5: APR 05, 2026 - 19:50:50
D6: Synthetic Feed DHA (Online) - Under no reaction conditions
D8: Synthetic Feed blend (STCB), online from R5
D9: CARBON# | E9: Paraffin | F9: I-Paraffins | G9: Aromatics | H9: Naphthenes | I9: Olefins | J9: Oxygenates | K9: Plus | L9: TOTAL
D10: 1 | E10: -- | F10: -- | G10: -- | H10: -- | I10: -- | J10: -- | K10: -- | L10: 0
D11: 2 | E11: -- | F11: -- | G11: -- | H11: -- | I11: -- | J11: -- | K11: -- | L11: 0
D12: 3 | E12: -- | F12: -- | G12: -- | H12: -- | I12: -- | J12: -- | K12: -- | L12: 0
D13: 4 | E13: 0.002012269 | F13: 0.000497388 | G13: -- | H13: -- | I13: -- | J13: -- | K13: -- | L13: 0.002509656
D14: 5 | E14: 0.006954285 | F14: 0.005316882 | G14: -- | H14: 0.001348769 | I14: -- | J14: -- | K14: -- | L14: 0.013619935
D15: 6 | E15: 86.080444 | F15: 0.42624071 | G15: -- | H15: 0.58100563 | I15: -- | J15: -- | K15: -- | L15: 87.087692
D16: 7 | E16: 9.4722185 | F16: 0.010982258 | G16: -- | H16: 0.004822898 | I16: -- | J16: -- | K16: -- | L16: 9.4880238
D17: 8 | E17: 3.2154758 | F17: 0.030950319 | G17: -- | H17: 0.049831167 | I17: -- | J17: -- | K17: -- | L17: 3.2962573
D18: 9 | E18: 0.011423086 | F18: 0.009861145 | G18: 0.001813711 | H18: 0.002859483 | I18: -- | J18: -- | K18: -- | L18: 0.025957424
D19: 10 | E19: 0.008134374 | F19: 0.005598063 | G19: 0.002172304 | H19: 0.002434537 | I19: -- | J19: -- | K19: -- | L19: 0.018339278
D20: 11 | E20: 0.004806483 | F20: 0.007187498 | G20: 0.003648059 | H20: -- | I20: -- | J20: -- | K20: -- | L20: 0.01564204
D21: 12 | E21: 0.001373788 | F21: -- | G21: 0.003038012 | H21: -- | I21: -- | J21: -- | K21: -- | L21: 0.0044118
D22: 13 | E22: -- | F22: -- | G22: -- | H22: -- | I22: -- | J22: -- | K22: -- | L22: 0
D23: 14 | E23: -- | F23: -- | G23: -- | H23: -- | I23: -- | J23: -- | K23: -- | L23: 0
D24: 15 | E24: -- | F24: -- | G24: -- | H24: -- | I24: -- | J24: -- | K24: -- | L24: 0
D26: TOTAL | E26: 98.802841 | F26: 0.49663424 | G26: 0.010672087 | H26: 0.64230251 | I26: 0 | J26: 0 | K26: 0 | L26: 99.952446
K27: UNKNOWNS | L27: 0.047558017
K28: GRAND_TOTAL | L28: 100.00001

Sheet Raw Data
A1: Date | B1: TOS_h | C1: Reactor | D1: Time | E1: 10i1TIC02, oC | F1: 10i2TIC02, oC | G1: 10i1PIC01, barg | H1: 10i2PIC01, barg | I1: H2 flow, Nml/hr | Q1: Total H2 flow, gm/hr | R1: N2 Dilution Flow, Nml/hr | Z1: Oven Temperature | AA1: HC flow, gms/hr | AI1: GC Composition, % vol | AL1: Molecular. Wt | AM1: Carbon, wt% | AN1: Hydrogen, wt% | AO1: RON | AP1: Paraffins, wt% | BE1: Iso Paraffins, wt% | BT1: Aromatics, wt% | CI1: Naphthenes, wt% | CX1: Olefins, wt% | DM1: Unknowns | DN1: Total | DP1: C3 & Below | DQ1: Propane | DR1: i-Butane | DS1: n-Butane | DT1: i-Pentane | DU1: n-Pentane | DV1: 2,2-Dimethylbutane | DW1: 2,3-Dimethylbutane | DX1: 2-Methylpentane | DY1: 3-Methylpentane | DZ1: n-Hexane | EA1: C6-C7 Unknowns | EB1: Methylcyclopentane | EC1: 2-Methylhexane | ED1: 3-Methylhexane | EE1: n-Heptane | EF1: C7-C8 Unknowns | EG1: n-Octane | EH1: C8 Plus
I2: 01i14FIC01 | J2: 01i14FIC02 | K2: 01i14FIC03 | L2: 01i14FIC04 | M2: 01i14FIC05 | N2: 01i14FIC06 | O2: 01i14FIC07 | P2: 01i14FIC08 | Q2: 01i14FI01 | R2: 10i1FIC01 | S2: 10i1FIC02 | T2: 10i1FIC03 | U2: 10i1FIC04 | V2: 10i2FIC05 | W2: 10i2FIC06 | X2: 10i2FIC07 | Y2: 10i2FIC08 | Z2: 10i2TIC01, oC | AA2: 02i2FIC01 | AB2: 02i2FIC02 | AC2: 02i2FIC03 | AD2: 02i2FIC04 | AE2: 02i2FIC05 | AF2: 02i2FIC06 | AG2: 02i2FIC07 | AH2: 02i2FIC08 | AI2: H2 | AJ2: N2 | AP2: C1 | AQ2: C2 | AR2: C3 | AS2: C4 | AT2: C5 | AU2: C6 | AV2: C7 | AW2: C8 | AX2: C9 | AY2: C10 | AZ2: C11 | BA2: C12 | BB2: C13 | BC2: C14 | BD2: C15 | BE2: C1 | BF2: C2 | BG2: C3 | BH2: C4 | BI2: C5 | BJ2: C6 | BK2: C7 | BL2: C8 | BM2: C9 | BN2: C10 | BO2: C11 | BP2: C12 | BQ2: C13 | BR2: C14 | BS2: C15 | BT2: C1 | BU2: C2 | BV2: C3 | BW2: C4 | BX2: C5 | BY2: C6 | BZ2: C7 | CA2: C8 | CB2: C9 | CC2: C10 | CD2: C11 | CE2: C12 | CF2: C13 | CG2: C14 | CH2: C15 | CI2: C1 | CJ2: C2 | CK2: C3 | CL2: C4 | CM2: C5 | CN2: C6 | CO2: C7 | CP2: C8 | CQ2: C9 | CR2: C10 | CS2: C11 | CT2: C12 | CU2: C13 | CV2: C14 | CW2: C15 | CX2: C1 | CY2: C2 | CZ2: C3 | DA2: C4 | DB2: C5 | DC2: C6 | DD2: C7 | DE2: C8 | DF2: C9 | DG2: C10 | DH2: C11 | DI2: C12 | DJ2: C13 | DK2: C14 | DL2: C15 | DM2: wt% | DN2: wt%
A3: 46120 | C3: 1 | D3: 13:15:12 | E3: 190 | F3: 190.1 | G3: 24.0046 | H3: 24.0017 | I3: 819.532 | J3: 819.636 | K3: 0 | L3: 0 | M3: 819.825 | N3: 820.086 | O3: 0 | P3: 0 | Q3: 0.264749 | R3: 1999.97 | S3: 1998.71 | T3: 0 | U3: 0 | V3: 1999.78 | W3: 2000.14 | X3: 0 | Y3: 0 | Z3: 219.7 | AA3: 1.99884 | AB3: 1.99683 | AC3: -0.0733567 | AD3: 0.00669135 | AE3: 1.99633 | AF3: 2.00026 | AG3: -0.112909 | AH3: 0.26966 | AI3: 23.581826 | AJ3: 58.624301 | AL3: 88.415359 | AM3: 83.620697 | AN3: 15.947486 | AO3: 26.55468 | AP3: 0 | AQ3: 0 | AR3: 0.062192425 | AS3: 0.14041644 | AT3: 0.26477492 | AU3: 81.083046 | AV3: 8.5302315 | AW3: 2.6210358 | AX3: 0 | AY3: 0 | AZ3: 0 | BA3: 0 | BB3: 0 | BC3: 0 | BD3: 0 | BE3: 0 | BF3: 0 | BG3: 0 | BH3: 0.35577157 | BI3: 0.43755233 | BJ3: 2.7414827 | BK3: 0.93520123 | BL3: 0 | BM3: 0 | BN3: 0 | BO3: 0 | BP3: 0 | BQ3: 0 | BR3: 0 | BS3: 0 | BT3: 0 | BU3: 0 | BV3: 0 | BW3: 0 | BX3: 0 | BY3: 0 | BZ3: 0 | CA3: 0 | CB3: 0 | CC3: 0 | CD3: 0 | CE3: 0 | CF3: 0 | CG3: 0 | CH3: 0 | CI3: 0 | CJ3: 0 | CK3: 0 | CL3: 0 | CM3: 0 | CN3: 0.45878011 | DM3: 2.3695371 | DN3: =SUM(AP3:DM3) -> 100.00002 | DP3: 0.0028669657 | DQ3: 0.062284186 | DR3: 0.35629648 | DS3: 0.14062363 | DT3: 0.43819794 | DU3: 0.26516557 | DV3: 0.032030974 | DW3: 0.16747658 | DX3: 1.4466473 | DY3: 1.0993727 | DZ3: 81.202682 | EA3: 0.50374722 | EB3: 0.45945701 | EC3: 0.50759774 | ED3: 0.42898336 | EE3: 8.5428171 | EF3: 1.0807484 | EG3: 2.6249032 | EH3: 0.6381098
A4: 46120 | C4: 2 | D4: 15:19:22 | E4: 189.7 | F4: 189.8 | G4: 24.0148 | H4: 24.0003 | I4: 781.55 | J4: 782.924 | K4: 0 | L4: 0 | M4: 781.596 | N4: 780.465 | O4: 0 | P4: 0 | Q4: 0.332457 | R4: 2000.3 | S4: 1998.59 | T4: 0 | U4: 0 | V4: 1999.87 | W4: 2000.24 | X4: 0 | Y4: 0 | Z4: 220 | AA4: 2.00117 | AB4: 2.00103 | AC4: -0.0827623 | AD4: -0.0185442 | AE4: 1.99867 | AF4: 1.99657 | AG4: -0.114037 | AH4: -0.257098 | AI4: 22.166466 | AJ4: 59.290763 | AL4: 88.289795 | AM4: 83.610947 | AN4: 16.068733 | AO4: 26.527403 | AP4: 0 | AQ4: 0 | AR4: 0.036769748 | AS4: 0.045819584 | AT4: 0.064356632 | AU4: 82.752235 | AV4: 8.3845625 | AW4: 2.3690841 | AX4: 0 | AY4: 0 | AZ4: 0 | BA4: 0 | BB4: 0 | BC4: 0 | BD4: 0 | BE4: 0 | BF4: 0 | BG4: 0 | BH4: 0.14659333 | BI4: 0.11668522 | BJ4: 3.0759048 | BK4: 0.92185974 | BL4: 0 | BM4: 0 | BN4: 0 | BO4: 0 | BP4: 0 | BQ4: 0 | BR4: 0 | BS4: 0 | BT4: 0 | BU4: 0 | BV4: 0 | BW4: 0 | BX4: 0 | BY4: 0 | BZ4: 0 | CA4: 0 | CB4: 0 | CC4: 0 | CD4: 0 | CE4: 0 | CF4: 0 | CG4: 0 | CH4: 0 | CI4: 0 | CJ4: 0 | CK4: 0 | CL4: 0 | CM4: 0 | CN4: 0.48299909 | DM4: 1.6031146 | DN4: =SUM(AP4:DM4) -> 99.999985 | DP4: 0.0020376805 | DQ4: 0.036790256 | DR4: 0.1466751 | DS4: 0.04584514 | DT4: 0.1167503 | DU4: 0.064392529 | DV4: 0.028997583 | DW4: 0.17084102 | DX4: 1.6194693 | DY4: 1.2583125 | DZ4: 82.798393 | EA4: 0.48698446 | EB4: 0.48326847 | EC4: 0.49346334 | ED4: 0.42891061 | EE4: 8.3892384 | EF4: 0.90384263 | EG4: 2.3704054 | EH4: 0.15539023
A5: 46120 | C5: 5 | D5: 17:23:32 | E5: 190 | F5: 190 | G5: 23.9945 | H5: 24.0061 | I5: 754.74 | J5: 757.574 | K5: 0 | L5: 0 | M5: 755.854 | N5: 752.214 | O5: 0 | P5: 0 | Q5: 0.248383 | R5: 2000.27 | S5: 1999.94 | T5: 0 | U5: 0 | V5: 1999.88 | W5: 2000.42 | X5: 0 | Y5: 0 | Z5: 219.9 | AA5: 2.00073 | AB5: 1.99892 | AC5: -0.076165 | AD5: -0.00398628 | AE5: 1.99926 | AF5: 1.99631 | AG5: -0.115156 | AH5: 0.00374242 | AI5: 23.366536 | AJ5: 58.075819 | AL5: 88.127716 | AM5: 83.605835 | AN5: 16.272116 | AO5: 24.783337 | AP5: 0 | AQ5: 0 | AR5: 0 | AS5: 0.008234838 | AT5: 0.021623714 | AU5: 85.969894 | AV5: 9.5062857 | AW5: 3.1488898 | AX5: 0 | AY5: 0 | AZ5: 0 | BA5: 0 | BB5: 0 | BC5: 0 | BD5: 0 | BE5: 0 | BF5: 0 | BG5: 0 | BH5: 0.0022863878 | BI5: 0.017265417 | BJ5: 0.4426221 | BK5: 0.024941638 | BL5: 0 | BM5: 0 | BN5: 0 | BO5: 0 | BP5: 0 | BQ5: 0 | BR5: 0 | BS5: 0 | BT5: 0 | BU5: 0 | BV5: 0 | BW5: 0 | BX5: 0 | BY5: 0 | BZ5: 0 | CA5: 0 | CB5: 0 | CC5: 0 | CD5: 0 | CE5: 0 | CF5: 0 | CG5: 0 | CH5: 0 | CI5: 0 | CJ5: 0 | CK5: 0 | CL5: 0 | CM5: 0 | CN5: 0.55082244 | DM5: 0.30714354 | DN5: =SUM(AP5:DM5) -> 100.00001 | DP5: 0.0022871955 | DR5: 0.002130724 | DS5: 0.0082377475 | DT5: 0.017271515 | DU5: 0.021631353 | DV5: 0.002108884 | DW5: 0.049772982 | DX5: 0.39089659 | DZ5: 86.000259 | EA5: 0.55101699 | EC5: 0.01129413 | ED5: 9.5096436 | EE5: 0.13413477 | EF5: 3.150002 | EG5: 0.1243696
A6: 46120 | C6: 6 | D6: 19:27:42 | E6: 190 | F6: 190 | G6: 24.0003 | H6: 23.9902 | I6: 784.381 | J6: 784.822 | K6: 0 | L6: 0 | M6: 784.816 | N6: 782.414 | O6: 0 | P6: 0 | Q6: 0.262405 | R6: 2000.71 | S6: 1999.71 | T6: 0 | U6: 0 | V6: 1999.91 | W6: 2000.27 | X6: 0 | Y6: 0 | Z6: 219.9 | AA6: 1.99943 | AB6: 2.00022 | AC6: -0.0840526 | AD6: -0.00220196 | AE6: 2.00298 | AF6: 1.99995 | AG6: -0.0934312 | AH6: -0.0355248 | AI6: 22.253473 | AJ6: 59.348592 | AL6: 88.25737 | AM6: 83.609375 | AN6: 15.994471 | AO6: 28.051004 | AP6: 0 | AQ6: 0 | AR6: 0.071534544 | AS6: 0.049571723 | AT6: 0.02370123 | AU6: 80.745018 | AV6: 7.5231051 | AW6: 1.7587446 | AX6: 0 | AY6: 0 | AZ6: 0 | BA6: 0 | BB6: 0 | BC6: 0 | BD6: 0 | BE6: 0 | BF6: 0 | BG6: 0 | BH6: 0.23335926 | BI6: 0.09594138 | BJ6: 5.3967938 | BK6: 1.5692658 | BL6: 0 | BM6: 0 | BN6: 0 | BO6: 0 | BP6: 0 | BQ6: 0 | BR6: 0 | BS6: 0 | BT6: 0 | BU6: 0 | BV6: 0 | BW6: 0 | BX6: 0 | BY6: 0 | BZ6: 0 | CA6: 0 | CB6: 0 | CC6: 0 | CD6: 0 | CE6: 0 | CF6: 0 | CG6: 0 | CH6: 0 | CI6: 0 | CJ6: 0 | CK6: 0 | CL6: 0 | CM6: 0 | CN6: 0.44129381 | DM6: 2.0916877 | DN6: =SUM(AP6:DM6) -> 100.00002 | DP6: 0.0013643811 | DQ6: 0.071562313 | DR6: 0.23344986 | DS6: 0.049590968 | DT6: 0.095978625 | DU6: 0.02371043 | DV6: 0.056568887 | DW6: 0.31616277 | DX6: 2.9737091 | DY6: 2.0524483 | DZ6: 80.776367 | EA6: 0.74855006 | EB6: 0.44146511 | EC6: 0.81051385 | ED6: 0.75936115 | EE6: 7.5260258 | EF6: 1.2701463 | EG6: 1.7594274 | EH6: 0.033622168
A7: 46120 | C7: 1 | D7: 21:31:52 | E7: 190 | F7: 190 | G7: 24.0133 | H7: 23.9945 | I7: 746.34 | J7: 746.422 | K7: 0 | L7: 0 | M7: 746.822 | N7: 745.886 | O7: 0 | P7: 0 | Q7: 0.359877 | R7: 2001.57 | S7: 1999.87 | T7: 0 | U7: 0 | V7: 1999.55 | W7: 1999.09 | X7: 0 | Y7: 0 | Z7: 220 | AA7: 2.00148 | AB7: 2.00034 | AC7: -0.0779799 | AD7: -0.00732437 | AE7: 2.00146 | AF7: 2.00316 | AG7: -0.0661632 | AH7: -0.243327 | AI7: 24.104657 | AJ7: 58.758333 | AL7: 88.218704 | AM7: 83.607758 | AN7: 16.098692 | AO7: 26.610477 | AP7: 0 | AQ7: 0 | AR7: 0.042025063 | AS7: 0.028201008 | AT7: 0.0136956 | AU7: 83.10537 | AV7: 8.3135891 | AW7: 2.2755797 | AX7: 0 | AY7: 0 | AZ7: 0 | BA7: 0 | BB7: 0 | BC7: 0 | BD7: 0 | BE7: 0 | BF7: 0 | BG7: 0 | BH7: 0.13843997 | BI7: 0.0560828 | BJ7: 3.2100019 | BK7: 0.93117154 | BL7: 0 | BM7: 0 | BN7: 0 | BO7: 0 | BP7: 0 | BQ7: 0 | BR7: 0 | BS7: 0 | BT7: 0 | BU7: 0 | BV7: 0 | BW7: 0 | BX7: 0 | BY7: 0 | BZ7: 0 | CA7: 0 | CB7: 0 | CC7: 0 | CD7: 0 | CE7: 0 | CF7: 0 | CG7: 0 | CH7: 0 | CI7: 0 | CJ7: 0 | CK7: 0 | CL7: 0 | CM7: 0 | CN7: 0.46289611 | DM7: 1.4229755 | DN7: =SUM(AP7:DM7) -> 100.00003 | DP7: 0.0010367234 | DQ7: 0.04203691 | DR7: 0.13847899 | DS7: 0.028208958 | DT7: 0.05609861 | DU7: 0.013699461 | DV7: 0.032620303 | DW7: 0.18171835 | DX7: 1.6962819 | DY7: 1.3002863 | DZ7: 83.128792 | EA7: 0.50311363 | EB7: 0.46302661 | EC7: 0.49657971 | ED7: 0.43485433 | EE7: 8.3159323 | EF7: 0.86751813 | EG7: 2.276221 | EH7: 0.023488384
A8: 46120 | C8: 2 | D8: 23:36:02 | E8: 190 | F8: 190 | G8: 23.996 | H8: 23.9988 | I8: 766.046 | J8: 766.293 | K8: 0 | L8: 0 | M8: 766.319 | N8: 765.254 | O8: 0 | P8: 0 | Q8: 0.185756 | R8: 2000.08 | S8: 2000.41 | T8: 0 | U8: 0 | V8: 1999.95 | W8: 1999.73 | X8: 0 | Y8: 0 | Z8: 220 | AA8: 2 | AB8: 2.00019 | AC8: -0.0613518 | AD8: 0.00856933 | AE8: 2.0012 | AF8: 1.99928 | AG8: -0.0882053 | AH8: -0.0252444 | AI8: 21.805334 | AJ8: 60.018318 | AL8: 88.220924 | AM8: 83.607803 | AN8: 16.112299 | AO8: 26.479305 | AP8: 0 | AQ8: 0 | AR8: 0.036710881 | AS8: 0.024184916 | AT8: 0.011443716 | AU8: 83.269905 | AV8: 8.4190588 | AW8: 2.3493876 | AX8: 0 | AY8: 0 | AZ8: 0 | BA8: 0 | BB8: 0 | BC8: 0 | BD8: 0 | BE8: 0 | BF8: 0 | BG8: 0 | BH8: 0.12142396 | BI8: 0.048441142 | BJ8: 3.0429361 | BK8: 0.86683172 | BL8: 0 | BM8: 0 | BN8: 0 | BO8: 0 | BP8: 0 | BQ8: 0 | BR8: 0 | BS8: 0 | BT8: 0 | BU8: 0 | BV8: 0 | BW8: 0 | BX8: 0 | BY8: 0 | BZ8: 0 | CA8: 0 | CB8: 0 | CC8: 0 | CD8: 0 | CE8: 0 | CF8: 0 | CG8: 0 | CH8: 0 | CI8: 0 | CJ8: 0 | CK8: 0 | CL8: 0 | CM8: 0 | CN8: 0.47651261 | DM8: 1.3331186 | DN8: =SUM(AP8:DM8) -> 99.999955 | DP8: 0.0008638578 | DQ8: 0.036720771 | DR8: 0.12145667 | DS8: 0.024191432 | DT8: 0.048454192 | DU8: 0.011446799 | DV8: 0.030724382 | DW8: 0.17209703 | DX8: 1.593253 | DY8: 1.2476814 | DZ8: 83.292336 | EA8: 0.46989584 | EB8: 0.47664097 | EC8: 0.46421194 | ED8: 0.40285328 | EE8: 8.4213266 | EF8: 0.81409866 | EG8: 2.3500204 | EH8: 0.02174155
A9: 46121 | C9: 5 | D9: 01:40:12 | E9: 190 | F9: 190 | G9: 23.9612 | H9: 24.0075 | I9: 763.178 | J9: 760.712 | K9: 0 | L9: 0 | M9: 761.804 | N9: 764.329 | O9: 0 | P9: 0 | Q9: 0.292864 | R9: 1999.76 | S9: 1999.81 | T9: 0 | U9: 0 | V9: 2000.12 | W9: 2000.27 | X9: 0 | Y9: 0 | Z9: 219.9 | AA9: 2.00191 | AB9: 2.00096 | AC9: -0.0633015 | AD9: -0.00282936 | AE9: 1.99793 | AF9: 2.00178 | AG9: -0.0982186 | AH9: 0.00154748 | AI9: 23.407452 | AJ9: 58.500476 | AL9: 88.090355 | AM9: 83.605171 | AN9: 16.287558 | AO9: 24.812828 | AP9: 0 | AQ9: 0 | AR9: 0 | AS9: 0.0017248455 | AT9: 0.0059430422 | AU9: 86.138435 | AV9: 9.4945898 | AW9: 3.1289647 | AX9: 0 | AY9: 0 | AZ9: 0 | BA9: 0 | BB9: 0 | BC9: 0 | BD9: 0 | BE9: 0 | BF9: 0 | BG9: 0 | BH9: 0 | BI9: 0.0046695694 | BJ9: 0.42853561 | BK9: 0.0081720389 | BL9: 0 | BM9: 0 | BN9: 0 | BO9: 0 | BP9: 0 | BQ9: 0 | BR9: 0 | BS9: 0 | BT9: 0 | BU9: 0 | BV9: 0 | BW9: 0 | BX9: 0 | BY9: 0 | BZ9: 0 | CA9: 0 | CB9: 0 | CC9: 0 | CD9: 0 | CE9: 0 | CF9: 0 | CG9: 0 | CH9: 0 | CI9: 0 | CJ9: 0 | CK9: 0 | CL9: 0 | CM9: 0 | CN9: 0.57978088 | DM9: 0.20915928 | DN9: =SUM(AP9:DM9) -> 99.999975 | DP9: 0.0017252481 | DQ9: 0.0046706591 | DR9: 0.0059444294 | DS9: 0.0015077635 | DT9: 0.041467022 | DU9: 0.38566086 | DV9: 86.158539 | DW9: 0.57991618 | DX9: 0.0041954946 | DY9: 0.0039784517 | DZ9: 0.010130772 | EA9: 9.4968061 | EB9: 0.10982592 | EC9: 3.1296949 | ED9: 0.065932862
A10: 46121 | C10: 6 | D10: 03:44:23 | E10: 190 | F10: 190 | G10: 23.9554 | H10: 23.9902 | I10: 802.076 | J10: 802.547 | K10: 0 | L10: 0 | M10: 801.936 | N10: 801.84 | O10: 0 | P10: 0 | Q10: 0.270651 | R10: 2000.14 | S10: 2000.61 | T10: 0 | U10: 0 | V10: 1999.92 | W10: 1998.98 | X10: 0 | Y10: 0 | Z10: 220 | AA10: 1.99939 | AB10: 2.00044 | AC10: -0.0599026 | AD10: -0.00318803 | AE10: 2.00261 | AF10: 1.99866 | AG10: -0.0803121 | AH10: -0.0345935 | AI10: 22.594453 | AJ10: 59.152436 | AL10: 88.23864 | AM10: 83.608643 | AN10: 16.007288 | AO10: 27.970734 | AP10: 0 | AQ10: 0 | AR10: 0.072446726 | AS10: 0.044775739 | AT10: 0.011734557 | AU10: 80.987595 | AV10: 7.5566211 | AW10: 1.7823794 | AX10: 0 | AY10: 0 | AZ10: 0 | BA10: 0 | BB10: 0 | BC10: 0 | BD10: 0 | BE10: 0 | BF10: 0 | BG10: 0 | BH10: 0.22738113 | BI10: 0.076894455 | BJ10: 5.2709808 | BK10: 1.5156231 | BL10: 0 | BM10: 0 | BN10: 0 | BO10: 0 | BP10: 0 | BQ10: 0 | BR10: 0 | BS10: 0 | BT10: 0 | BU10: 0 | BV10: 0 | BW10: 0 | BX10: 0 | BY10: 0 | BZ10: 0 | CA10: 0 | CB10: 0 | CC10: 0 | CD10: 0 | CE10: 0 | CF10: 0 | CG10: 0 | CH10: 0 | CI10: 0 | CJ10: 0 | CK10: 0 | CL10: 0 | CM10: 0 | CN10: 0.44187012 | DM10: 2.0117118 | DN10: =SUM(AP10:DM10) -> 100.00001 | DP10: 0.0010217624 | DQ10: 0.072466612 | DR10: 0.22744355 | DS10: 0.044788029 | DT10: 0.076915562 | DU10: 0.011737778 | DV10: 0.055982776 | DW10: 0.31539735 | DX10: 2.8949969 | DY10: 2.0060503 | DZ10: 81.009819 | EA10: 0.75283349 | EB10: 0.44199142 | EC10: 0.78428078 | ED10: 0.7317583 | EE10: 7.5586948 | EF10: 1.2195942 | EG10: 1.7828685 | EH10: 0.011369604
A11: 46121 | C11: 1 | D11: 05:48:33 | E11: 190 | F11: 190 | G11: 24.0032 | H11: 23.9931 | I11: 800.113 | J11: 800.794 | K11: 0 | L11: 0 | M11: 799.955 | N11: 800.322 | O11: 0 | P11: 0 | Q11: 0.240064 | R11: 1999.91 | S11: 2000.13 | T11: 0 | U11: 0 | V11: 1999.66 | W11: 1999.64 | X11: 0 | Y11: 0 | Z11: 219.9 | AA11: 1.99948 | AB11: 1.99969 | AC11: -0.0616554 | AD11: -0.00113907 | AE11: 1.99806 | AF11: 2.0023 | AG11: -0.133934 | AH11: -0.0220774 | AI11: 24.425367 | AJ11: 58.728386 | AL11: 88.217499 | AM11: 83.607643 | AN11: 16.103294 | AO11: 26.55908 | AP11: 0 | AQ11: 0 | AR11: 0.042004023 | AS11: 0.026720399 | AT11: 0.010588287 | AU11: 83.170242 | AV11: 8.35114 | AW11: 2.2993696 | AX11: 0 | AY11: 0 | AZ11: 0 | BA11: 0 | BB11: 0 | BC11: 0 | BD11: 0 | BE11: 0 | BF11: 0 | BG11: 0 | BH11: 0.13786973 | BI11: 0.051444426 | BJ11: 3.1453612 | BK11: 0.9121232 | BL11: 0 | BM11: 0 | BN11: 0 | BO11: 0 | BP11: 0 | BQ11: 0 | BR11: 0 | BS11: 0 | BT11: 0 | BU11: 0 | BV11: 0 | BW11: 0 | BX11: 0 | BY11: 0 | BZ11: 0 | CA11: 0 | CB11: 0 | CC11: 0 | CD11: 0 | CE11: 0 | CF11: 0 | CG11: 0 | CH11: 0 | CI11: 0 | CJ11: 0 | CK11: 0 | CL11: 0 | CM11: 0 | CN11: 0.4591752 | DM11: 1.3939586 | DN11: =SUM(AP11:DM11) -> 99.999997 | DP11: 0.000822352 | DQ11: 0.042014547 | DR11: 0.13790427 | DS11: 0.026727093 | DT11: 0.051457316 | DU11: 0.010590941 | DV11: 0.032028299 | DW11: 0.17882405 | DX11: 1.6594604 | DY11: 1.2758365 | DZ11: 83.191078 | EA11: 0.50146371 | EB11: 0.45929024 | EC11: 0.48806638 | ED11: 0.42428535 | EE11: 8.3532324 | EF11: 0.84888107 | EG11: 2.2999456 | EH11: 0.01807352
A12: 46121 | C12: 2 | D12: 07:52:45 | E12: 190 | F12: 190 | G12: 24.0104 | H12: 24.0003 | I12: 773.706 | J12: 770.885 | K12: 0 | L12: 0 | M12: 772.512 | N12: 775.44 | O12: 0 | P12: 0 | Q12: 0.250211 | R12: 1999.65 | S12: 1999.36 | T12: 0 | U12: 0 | V12: 2000.2 | W12: 1998.77 | X12: 0 | Y12: 0 | Z12: 220 | AA12: 0.789375 | AB12: 1.13808 | AC12: -0.0575566 | AD12: 3.62769e-05 | AE12: -0.258702 | AF12: -1.83143 | AG12: -0.185263 | AH12: 0.0302421 | AI12: 21.840241 | AJ12: 60.39062 | AL12: 88.213226 | AM12: 83.607498 | AN12: 16.112036 | AO12: 26.507113 | AP12: 0 | AQ12: 0 | AR12: 0.039317522 | AS12: 0.025144458 | AT12: 0.0098485816 | AU12: 83.256012 | AV12: 8.4044666 | AW12: 2.3352902 | AX12: 0 | AY12: 0 | AZ12: 0 | BA12: 0 | BB12: 0 | BC12: 0 | BD12: 0 | BE12: 0 | BF12: 0 | BG12: 0 | BH12: 0.12782566 | BI12: 0.047998708 | BJ12: 3.078898 | BK12: 0.87130964 | BL12: 0 | BM12: 0 | BN12: 0 | BO12: 0 | BP12: 0 | BQ12: 0 | BR12: 0 | BS12: 0 | BT12: 0 | BU12: 0 | BV12: 0 | BW12: 0 | BX12: 0 | BY12: 0 | BZ12: 0 | CA12: 0 | CB12: 0 | CC12: 0 | CD12: 0 | CE12: 0 | CF12: 0 | CG12: 0 | CH12: 0 | CI12: 0 | CJ12: 0 | CK12: 0 | CL12: 0 | CM12: 0 | CN12: 0.46661776 | DM12: 1.3372741 | DN12: =SUM(AP12:DM12) -> 100 | DP12: 0.0008647467 | DQ12: 0.039326605 | DR12: 0.12785518 | DS12: 0.025150266 | DT12: 0.048009794 | DU12: 0.0098508568 | DV12: 0.032111879 | DW12: 0.17723283 | DX12: 1.6142468 | DY12: 1.2560178 | DZ12: 83.275246 | EA12: 0.48408529 | EB12: 0.46672556 | EC12: 0.46745327 | ED12: 0.40405768 | EE12: 8.4064083 | EF12: 0.81088841 | EG12: 2.3358297 | EH12: 0.018609818
A25: 46122 | C25: 5 | D25: 10:47:06 | E25: 190 | F25: 190 | G25: 23.9771 | H25: 24.0003 | I25: 810.658 | J25: 806.775 | K25: 0 | L25: 0 | M25: 808.276 | N25: 812.466 | O25: 0 | P25: 0 | Q25: 0.434997 | R25: 1999.69 | S25: 2000.43 | T25: 0 | U25: 0 | V25: 1999.48 | W25: 2000.4 | X25: 0 | Y25: 0 | Z25: 220 | AA25: 1.99552 | AB25: 1.9964 | AC25: -0.0586952 | AD25: -0.00135834 | AE25: 2.00153 | AF25: 2.00493 | AG25: -0.0506218 | AH25: 0.00568774 | AI25: 23.365182 | AJ25: 58.641352 | AL25: 88.093262 | AM25: 83.605247 | AN25: 16.278395 | AO25: 24.851723 | AP25: 0 | AQ25: 0 | AR25: 0 | AS25: 0.0066033001 | AT25: 0.017517582 | AU25: 86.101036 | AV25: 9.451642 | AW25: 3.0916703 | AX25: 0 | AY25: 0 | AZ25: 0 | BA25: 0 | BB25: 0 | BC25: 0 | BD25: 0 | BE25: 0 | BF25: 0 | BG25: 0 | BH25: 0.0019434597 | BI25: 0.01368668 | BJ25: 0.43947756 | BK25: 0.019623075 | BL25: 0 | BM25: 0 | BN25: 0 | BO25: 0 | BP25: 0 | BQ25: 0 | BR25: 0 | BS25: 0 | BT25: 0 | BU25: 0 | BV25: 0 | BW25: 0 | BX25: 0 | BY25: 0 | BZ25: 0 | CA25: 0 | CB25: 0 | CC25: 0 | CD25: 0 | CE25: 0 | CF25: 0 | CG25: 0 | CH25: 0 | CI25: 0 | CJ25: 0 | CK25: 0 | CL25: 0 | CM25: 0 | CN25: 0.59039086 | DM25: 0.26640782 | DN25: =SUM(AP25:DM25) -> 99.999999 | DP25: 0.0019440536 | DQ25: 0.0066053178 | DR25: 0.0014328742 | DS25: 0.013690861 | DT25: 0.017522933 | DU25: 0.0019310142 | DV25: 0.047891959 | DW25: 0.38978887 | DX25: 86.127342 | DY25: 0.59057122 | DZ25: 0.010328353 | EA25: 0.0093007162 | EB25: 0.010101865 | EC25: 9.4545298 | ED25: 0.12166159 | EE25: 3.0926149 | EF25: 0.10274826
A26: 46122 | C26: 6 | D26: 12:51:17 | E26: 190 | F26: 190 | G26: 23.9945 | H26: 23.9873 | I26: 855.956 | J26: 854.208 | K26: 0 | L26: 0 | M26: 855.68 | N26: 856.816 | O26: 0 | P26: 0 | Q26: 0.171192 | R26: 1999.55 | S26: 1999.88 | T26: 0 | U26: 0 | V26: 2000.05 | W26: 2000.76 | X26: 0 | Y26: 0 | Z26: 220 | AA26: 2.00409 | AB26: 1.99987 | AC26: -0.0663496 | AD26: -0.0070684 | AE26: 2.00199 | AF26: 1.99634 | AG26: -0.108407 | AH26: -0.0113871 | AI26: 22.941751 | AJ26: 60.183502 | AL26: 88.309021 | AM26: 83.610687 | AN26: 15.996447 | AO26: 27.690372 | AP26: 0 | AQ26: 0 | AR26: 0.061887246 | AS26: 0.043907992 | AT26: 0.020247986 | AU26: 81.120857 | AV26: 7.6584949 | AW26: 1.8632283 | AX26: 0 | AY26: 0 | AZ26: 0 | BA26: 0 | BB26: 0 | BC26: 0 | BD26: 0 | BE26: 0 | BF26: 0 | BG26: 0 | BH26: 0.20188843 | BI26: 0.08177948 | BJ26: 4.9241047 | BK26: 1.5051723 | BL26: 0 | BM26: 0 | BN26: 0 | BO26: 0 | BP26: 0 | BQ26: 0 | BR26: 0 | BS26: 0 | BT26: 0 | BU26: 0 | BV26: 0 | BW26: 0 | BX26: 0 | BY26: 0 | BZ26: 0 | CA26: 0 | CB26: 0 | CC26: 0 | CD26: 0 | CE26: 0 | CF26: 0 | CG26: 0 | CH26: 0 | CI26: 0 | CJ26: 0 | CK26: 0 | CL26: 0 | CM26: 0 | CN26: 0.44770679 | DM26: 2.0707104 | DN26: =SUM(AP26:DM26) -> 99.999986 | DP26: 0.0033109563 | DQ26: 0.061921164 | DR26: 0.2019991 | DS26: 0.043932058 | DT26: 0.081824303 | DU26: 0.020259086 | DV26: 0.047105659 | DW26: 0.26527494 | DX26: 2.7109711 | DY26: 1.903452 | DZ26: 81.165321 | EA26: 0.68621928 | EB26: 0.44795221 | EC26: 0.78107733 | ED26: 0.72491992 | EE26: 7.6626925 | EF26: 1.2996428 | EG26: 1.8642496 | EH26: 0.027876235
A27: 46122 | C27: 1 | D27: 14:55:28 | E27: 190 | F27: 190 | G27: 24.0162 | H27: 23.9945 | I27: 847.186 | J27: 849.934 | K27: 0 | L27: 0 | M27: 849.486 | N27: 845.856 | O27: 0 | P27: 0 | Q27: 0.189193 | R27: 1999.08 | S27: 1999.19 | T27: 0 | U27: 0 | V27: 2000.1 | W27: 1998.88 | X27: 0 | Y27: 0 | Z27: 220 | AA27: 2.00099 | AB27: 1.99936 | AC27: -0.0579538 | AD27: -0.00589139 | AE27: 2.00004 | AF27: 1.98481 | AG27: -0.153703 | AH27: -0.0588924 | AI27: 24.693267 | AJ27: 58.199308 | AL27: 88.608261 | AM27: 83.617531 | AN27: 16.061209 | AO27: 25.661228 | AP27: 0 | AQ27: 0 | AR27: 0.039085288 | AS27: 0.026637917 | AT27: 0.0040656193 | AU27: 81.982841 | AV27: 8.7207832 | AW27: 3.4970307 | AX27: 0 | AY27: 0 | AZ27: 0 | BA27: 0 | BB27: 0 | BC27: 0 | BD27: 0 | BE27: 0 | BF27: 0 | BG27: 0 | BH27: 0.1334777 | BI27: 0.039185509 | BJ27: 2.6782608 | BK27: 0.80530018 | BL27: 0 | BM27: 0 | BN27: 0 | BO27: 0 | BP27: 0 | BQ27: 0 | BR27: 0 | BS27: 0 | BT27: 0 | BU27: 0 | BV27: 0 | BW27: 0 | BX27: 0 | BY27: 0 | BZ27: 0 | CA27: 0 | CB27: 0 | CC27: 0 | CD27: 0 | CE27: 0 | CF27: 0 | CG27: 0 | CH27: 0 | CI27: 0 | CJ27: 0 | CK27: 0 | CL27: 0 | CM27: 0 | CN27: 0.46456555 | DM27: 1.6087554 | DN27: =SUM(AP27:DM27) -> 99.999989 | DP27: 0.0007204142 | DQ27: 0.039113209 | DR27: 0.13357306 | DS27: 0.026656946 | DT27: 0.039213505 | DU27: 0.0040685236 | DV27: 0.026913324 | DW27: 0.14450115 | DX27: 1.3881416 | DY27: 1.120618 | DZ27: 82.041405 | EA27: 0.43761253 | EB27: 0.46489742 | EC27: 0.43259591 | ED27: 0.37327954 | EE27: 8.7270136 | EF27: 1.0951984 | EG27: 3.4995289 | EH27: 0.0049632727
A28: 46122 | C28: 2 | D28: 16:59:39 | E28: 190 | F28: 190 | G28: 23.9742 | H28: 23.9988 | I28: 758.153 | J28: 757.75 | K28: 0 | L28: 0 | M28: 758.299 | N28: 758.955 | O28: 0 | P28: 0 | Q28: 0.338746 | R28: 1998.9 | S28: 2000.1 | T28: 0 | U28: 0 | V28: 1999.94 | W28: 1999.95 | X28: 0 | Y28: 0 | Z28: 220 | AA28: 2.00224 | AB28: 1.99862 | AC28: -0.0561603 | AD28: -0.00636061 | AE28: 1.99698 | AF28: 2.00216 | AG28: -0.0841603 | AH28: -0.0185198 | AI28: 22.496629 | AJ28: 59.366862 | AL28: 88.581261 | AM28: 83.616257 | AN28: 16.088379 | AO28: 25.509985 | AP28: 0 | AQ28: 0 | AR28: 0.04009201 | AS28: 0.02666495 | AT28: 0.0033761237 | AU28: 82.160011 | AV28: 8.8690948 | AW28: 3.6518736 | AX28: 0 | AY28: 0 | AZ28: 0 | BA28: 0 | BB28: 0 | BC28: 0 | BD28: 0 | BE28: 0 | BF28: 0 | BG28: 0 | BH28: 0.13563178 | BI28: 0.037596811 | BJ28: 2.4783325 | BK28: 0.70121646 | BL28: 0 | BM28: 0 | BN28: 0 | BO28: 0 | BP28: 0 | BQ28: 0 | BR28: 0 | BS28: 0 | BT28: 0 | BU28: 0 | BV28: 0 | BW28: 0 | BX28: 0 | BY28: 0 | BZ28: 0 | CA28: 0 | CB28: 0 | CC28: 0 | CD28: 0 | CE28: 0 | CF28: 0 | CG28: 0 | CH28: 0 | CI28: 0 | CJ28: 0 | CK28: 0 | CL28: 0 | CM28: 0 | CN28: 0.4576259 | DM28: 1.4384559 | DN28: =SUM(AP28:DM28) -> 99.999972 | DQ28: 0.040113952 | DR28: 0.13570602 | DS28: 0.026679544 | DT28: 0.037617389 | DU28: 0.0033779715 | DV28: 0.028703738 | DW28: 0.14559467 | DX28: 1.2672386 | DY28: 1.0381516 | DZ28: 82.204979 | EA28: 0.42183146 | EB28: 0.45787635 | EC28: 0.38322765 | ED28: 0.31837255 | EE28: 8.8739491 | EF28: 0.95896703 | EG28: 3.6538723 | EH28: 0.0037510104
A29: 46122 | C29: 5 | D29: 19:03:49 | E29: 190 | F29: 190 | G29: 24.022 | H29: 24.0046 | I29: 720.778 | J29: 710.742 | K29: 0 | L29: 0 | M29: 716.358 | N29: 725.745 | O29: 0 | P29: 0 | Q29: 0.338087 | R29: 1999.52 | S29: 1999.51 | T29: 0 | U29: 0 | V29: 2000.02 | W29: 2000.04 | X29: 0 | Y29: 0 | Z29: 219.9 | AA29: 1.99839 | AB29: 2.00116 | AC29: -0.067394 | AD29: -0.00232141 | AE29: 2.00153 | AF29: 2.00146 | AG29: -0.240027 | AH29: -0.0313091 | AI29: 23.147193 | AJ29: 58.675473 | AL29: 88.439217 | AM29: 83.61203 | AN29: 16.28479 | AO29: 24.100986 | AP29: 0 | AQ29: 0 | AR29: 0 | AS29: 0 | AT29: 0.0015589115 | AU29: 84.494438 | AV29: 9.7401171 | AW29: 4.6050434 | AX29: 0 | AY29: 0 | AZ29: 0 | BA29: 0 | BB29: 0 | BC29: 0 | BD29: 0 | BE29: 0 | BF29: 0 | BG29: 0 | BH29: 0 | BI29: 0.0008560614 | BJ29: 0.41592088 | BK29: 0 | BL29: 0 | BM29: 0 | BN29: 0 | BO29: 0 | BP29: 0 | BQ29: 0 | BR29: 0 | BS29: 0 | BT29: 0 | BU29: 0 | BV29: 0 | BW29: 0 | BX29: 0 | BY29: 0 | BZ29: 0 | CA29: 0 | CB29: 0 | CC29: 0 | CD29: 0 | CE29: 0 | CF29: 0 | CG29: 0 | CH29: 0 | CI29: 0 | CJ29: 0 | CK29: 0 | CL29: 0 | CM29: 0 | CN29: 0.56256455 | DM29: 0.17947623 | DN29: =SUM(AP29:DM29) -> 99.999975 | DP29: 0.0008562281 | DQ29: 0.001559215 | DR29: 0.0011883206 | DS29: 0.037639387 | DT29: 0.37717414 | DU29: 84.510887 | DV29: 0.56267411 | DW29: 0.010556314 | DX29: 9.742013 | DY29: 0.12996434 | DZ29: 4.6059399 | EA29: 0.019541545
