Workbook

Sheet P. Yields - WABT 210 Act Fe (2)
C3: C5/C6 ISOMERISATION - Horizon-2 Programme - DGD_Patent_Run - @ WABT 210 deg C - Actual Run Conditions
G5: 210 | H5: 210 | I5: 210
C6: No | D6: Component ↓ | E6: UOM | G6: Z-700A | H6: Athos-1 | I6: Athos-3
C7: 1 | D7: Hydrogen | E7: wt% | G7: -0.059111209 | H7: -0.046635493 | I7: -0.07593812
C8: 2 | D8: Methane | E8: wt% | G8: 0.0019828472 | H8: 0.0014070799 | I8: 0.0029258093
C9: 3 | D9: Ethane | E9: wt% | G9: 0.0019554169 | H9: 0.0013847734 | I9: 0.0029093573
C10: 4 | D10: Propane | E10: wt% | G10: 0.14297252 | H10: 0.10075944 | I10: 0.21684833
C11: 5 | D11: n-Butane | E11: wt% | G11: 1.698259 | H11: 1.6933044 | I11: 1.7039007
C12: 6 | D12: iso-Butane | E12: wt% | G12: 2.7327347 | H12: 2.087099 | I12: 3.5822217
C13: 7 | D13: n-Pentane | E13: wt% | G13: 12.027647 | H13: 12.122874 | I13: 11.599571
C14: 8 | D14: iso-Pentane | E14: wt% | G14: 8.7807566 | H14: 8.6853951 | I14: 9.2090082
C15: 9 | D15: Cyclopentane | E15: wt% | G15: 0.27954973 | H15: 0.27966698 | I15: 0.27939405
C16: 10 | D16: n-Hexane | E16: wt% | G16: 14.439954 | H16: 14.72286 | I16: 13.218187
C17: 11 | D17: 2-Methyl Pentane | E17: wt% | G17: 7.9056713 | H17: 7.8466402 | I17: 8.2090946
C18: 12 | D18: 3-Methyl Pentane | E18: wt% | G18: 4.775473 | H18: 4.7093299 | I18: 5.0318694
... C29: 23 | D29: C8P | E29: wt% | G29: 12.067103 | H29: 12.647121 | I29: 11.337493
D30: Total → | E30: wt% | G30: =SUM(G7:G29) -> 100 | H30: =SUM(H7:H29) -> 100 | I30: =SUM(I7:I29) -> 100
C31: 24 | D31: Isomerate RON → | E31: - | G31: 54.533772 | H31: 53.664858 | I31: 57.485621
C32: 25 | D32: Isomerate MON → | E32: - | G32: 54.254103 | H32: 53.397028 | I32: 57.164756
C34: 26 | D34: C5+ Yield | E34: wt% | G34: 95.481207 | H34: 96.162681 | I34: 94.567132
C35: 27 | D35: C5+ Yield | E35: lv% | G35: 95.371126 | H35: 95.998792 | I35: 94.530978
C36: 28 | D36: C5+ product density | E36: g/cc | G36: 0.66826803 | H36: 0.66863713 | I36: 0.66775287
C37: 29 | D37: C5+ Isomearate MW | E37: g/g-mol | G37: 89.178268 | H37: 89.30651 | I37: 89.008908
C38: 30 | D38: H2 consumption | E38: Nm3/m3 | G38: 4.38724 | H38: 3.4612911 | I38: 5.6361351
C39: 31 | D39: Reid Vapour Pressure | E39: mbar | G39: 483.84731 | H39: 480.25566 | I39: 492.8252
C41: 32 | D41: ∆ RON (Prod - Feed) | E41: - | G41: =G31-44 -> 10.533772 | H41: =H31-44 -> 9.6648577 | I41: =I31-44 -> 13.485621
C42: 33 | D42: ∆ MON (Prod - Feed) | E42: - | G42: =G32-43.9 -> 10.354103 | H42: =H32-43.9 -> 9.4970279 | I42: =I32-43.9 -> 13.264756
C44: Simulation outuput - Operating Parameters
J45: Benefit USD/RON-BBL
C46: 34 | D46: Reactor Inlet Temp | E46: °C | G46: 203.35672 | H46: 204.2995 | I46: 201.45726 | J46: 1.25
C47: 35 | D47: Reactor Outlet Temp | E47: °C | G47: 213.32164 | H47: 212.85025 | I47: 214.27137
C48: 36 | D48: Reactor dT | E48: °C | G48: =G47-G46 -> 9.9649131 | H48: =H47-H46 -> 8.5507508 | I48: =I47-I46 -> 12.814106
C49: 37 | D49: WABT | E49: °C | G49: 210 | H49: 210 | I49: 210
C50: 38 | D50: Reactor Inlet Pre | E50: bar (g) | G50: 25 | H50: 25 | I50: 25
C51: 39 | D51: LHSV | E51: hr(-1) | G51: 1.4722119 | H51: 1.4757356 | I51: 1.4662483
C52: 40 | D52: WHSV | E52: hr(-1) | G52: 1.3904992 | H52: 1.980408 | I52: 1.5684832
C53: 41 | D53: H2:HC ratio | E53: mol:mol | G53: 3 | H53: 3 | I53: 3
C54: 42 | D54: Feed rate | E54: BPD | G54: 9429 | H54: 9429 | I54: 9429
C55: 43 | D55: Isomerate | E55: BPD | G55: =G54*G35/100 -> 8992.5434 | H55: =H54*H35/100 -> 9051.7261 | I55: =I54*I35/100 -> 8913.3259
C56: 44 | D56: ∆RON-BBL | E56: - | G56: =G55*G41 -> 94725.403 | H56: =H55*H41 -> 87483.645 | I56: =I55*I41 -> 120201.74
...

Sheet P. Yields - WABT 215 Act Fe (2)
C3: C5/C6 ISOMERISATION - Horizon-2 Programme - DGD_Patent_Run - @ WABT 215 deg C - Actual Run Conditions
C6: No | D6: Component ↓ | E6: UOM | G6: Z-700A | H6: Athos-1 | I6: Athos-3
C7: 1 | D7: Hydrogen | E7: wt% | G7: -0.064473811 | H7: -0.050490478 | I7: -0.083823601
C8: 2 | D8: Methane | E8: wt% | G8: 0.0029511765 | H8: 0.0020910142 | I8: 0.0043794335
C9: 3 | D9: Ethane | E9: wt% | G9: 0.0029579217 | H9: 0.0020918401 | I9: 0.0044225922
C10: 4 | D10: Propane | E10: wt% | G10: 0.21523197 | H10: 0.15139869 | I10: 0.32858398
C11: 5 | D11: n-Butane | E11: wt% | G11: 1.7053241 | H11: 1.6984652 | I11: 1.7132481
C12: 6 | D12: iso-Butane | E12: wt% | G12: 2.9230831 | H12: 2.2249435 | I12: 3.8580362
C13: 7 | D13: n-Pentane | E13: wt% | G13: 11.768207 | H13: 11.88452 | I13: 11.251657
C14: 8 | D14: iso-Pentane | E14: wt% | G14: 9.0404557 | H14: 8.9239373 | I14: 9.557273
C15: 9 | D15: Cyclopentane | E15: wt% | G15: 0.27933549 | H15: 0.27951218 | I15: 0.27910096
C16: 10 | D16: n-Hexane | E16: wt% | G16: 13.674048 | H16: 14.007373 | I16: 12.267938
C17: 11 | D17: 2-Methyl Pentane | E17: wt% | G17: 8.0913871 | H17: 8.0066028 | I17: 8.4773952
C18: 12 | D18: 3-Methyl Pentane | E18: wt% | G18: 4.964958 | H18: 4.8934424 | I18: 5.2362763
... C29: 23 | D29: C8P | E29: wt% | G29: 11.978526 | H29: 12.580011 | I29: 11.223706
D30: Total → | E30: wt% | G30: =SUM(G7:G29) -> 100 | H30: =SUM(H7:H29) -> 100 | I30: =SUM(I7:I29) -> 100
C31: 24 | D31: Isomerate RON → | E31: - | G31: 56.059128 | H31: 55.137259 | I31: 59.105137
C32: 25 | D32: Isomerate MON → | E32: - | G32: 55.75342 | H32: 54.843986 | I32: 58.756466
C34: 26 | D34: C5+ Yield | E34: wt% | G34: 95.214926 | H34: 95.9715 | I34: 94.175153
C35: 27 | D35: C5+ Yield | E35: lv% | G35: 95.120456 | H35: 95.819189 | I35: 94.162139
C36: 28 | D36: C5+ product density | E36: g/cc | G36: 0.66816051 | H36: 0.66855861 | I36: 0.66758983
C37: 29 | D37: C5+ Isomearate MW | E37: g/g-mol | G37: 89.142185 | H37: 89.28064 | I37: 88.956373
C38: 30 | D38: H2 consumption | E38: Nm3/m3 | G38: 7.1689442 | H38: 5.6141155 | I38: 9.3204777
C39: 31 | D39: Reid Vapour Pressure | E39: mbar | G39: 488.17324 | H39: 484.09776 | I39: 498.40693
C41: 32 | D41: ∆ RON (Prod - Feed) | E41: - | G41: =G31-44 -> 12.059128 | H41: =H31-44 -> 11.137259 | I41: =I31-44 -> 15.105137
C42: 33 | D42: ∆ MON (Prod - Feed) | E42: - | G42: =G32-43.9 -> 11.85342 | H42: =H32-43.9 -> 10.943986 | I42: =I32-43.9 -> 14.856466
C44: Simulation outuput - Operating Parameters
J45: Benefit USD/RON-BBL
C46: 34 | D46: Reactor Inlet Temp | E46: °C | G46: 207.56452 | H46: 208.60386 | I46: 205.47698 | J46: 1.25
C47: 35 | D47: Reactor Outlet Temp | E47: °C | G47: 218.71774 | H47: 218.19807 | I47: 219.76151
C48: 36 | D48: Reactor dT | E48: °C | G48: =G47-G46 -> 11.153221 | H48: =H47-H46 -> 9.5942032 | I48: =I47-I46 -> 14.284534
C49: 37 | D49: WABT | E49: °C | G49: 215 | H49: 215 | I49: 215
C50: 38 | D50: Reactor Inlet Pre | E50: bar (g) | G50: 25 | H50: 25 | I50: 25
C51: 39 | D51: LHSV | E51: hr(-1) | G51: 1.4722119 | H51: 1.4757356 | I51: 1.4662483
C52: 40 | D52: WHSV | E52: hr(-1) | G52: 1.3904992 | H52: 1.980408 | I52: 1.5684832
C53: 41 | D53: H2:HC ratio | E53: mol:mol | G53: 3 | H53: 3 | I53: 3
C54: 42 | D54: Feed rate | E54: BPD | G54: 9429 | H54: 9429 | I54: 9429
C55: 43 | D55: Isomerate | E55: BPD | G55: =G54*G35/100 -> 8968.9078 | H55: =H54*H35/100 -> 9034.7913 | I55: =I54*I35/100 -> 8878.5481
C56: 44 | D56: ∆RON-BBL | E56: - | G56: =G55*G41 -> 108157.2 | H56: =H55*H41 -> 100622.81 | I56: =I55*I41 -> 134111.68
C57: 45 | D57: Simple Benefit Analysis | E57: KUSD/Day | G57: =(G56*$J$46)/10^3 -> 135.1965 | H57: =(H56*$J$46)/10^3 -> 125.77851 | I57: =(I56*$J$46)/10^3 -> 167.6396 | L57: 1000
...

Sheet P. Yields - WABT 220 Act Fe (2)
C3: C5/C6 ISOMERISATION - Horizon-2 Programme - DGD_Patent_Run - @ WABT 220 deg C - Actual Run Conditions
N4: Experimental | O4: Experimental
N5: 220 0C | O5: 220 0C
C6: No | D6: Component ↓ | E6: UOM | G6: Z-700A | H6: Athos-1 | I6: Athos-3 | N6: ATHOS-1 | O6: ATHOS-3
C7: 1 | D7: Hydrogen | E7: wt% | G7: -0.071778869 | H7: -0.055760119 | I7: -0.07593812
C8: 2 | D8: Methane | E8: wt% | G8: 0.0043891961 | H8: 0.0031124392 | I8: 0.0029258093 | L8: Methane | M8: wof% | N8: 0 | O8: 0
C9: 3 | D9: Ethane | E9: wt% | G9: 0.0044712675 | H9: 0.003165693 | I9: 0.0029093573 | L9: Ethane | M9: wof% | N9: 0 | O9: 0
C10: 4 | D10: Propane | E10: wt% | G10: 0.32443498 | H10: 0.22845694 | I10: 0.21684833 | L10: Propane | M10: wof% | N10: 3.7960349 | O10: 10.350041
C11: 5 | D11: n-Butane | E11: wt% | G11: 1.7153828 | H11: 1.7058315 | I11: 1.7039007 | L11: n-Butane | M11: wof% | N11: 3.2262749 | O11: 3.8442695
C12: 6 | D12: iso-Butane | E12: wt% | G12: 3.1682022 | H12: 2.403596 | I12: 3.5822217 | L12: iso-Butane | M12: wof% | N12: 8.3316779 | O12: 19.184296
C13: 7 | D13: n-Pentane | E13: wt% | G13: 11.461386 | H13: 11.599097 | I13: 11.599571 | L13: n-Pentane | M13: wof% | N13: 12.537023 | O13: 11.985359
C14: 8 | D14: iso-Pentane | E14: wt% | G14: 9.3476722 | H14: 9.2096478 | I14: 9.2090082 | L14: iso-Pentane | M14: wof% | N14: 10.050346 | O14: 11.777568
C15: 9 | D15: Cyclopentane | E15: wt% | G15: 0.2790207 | H15: 0.27928399 | I15: 0.27939405 | L15: Cyclopentane | M15: wof% | N15: 0 | O15: 0
C16: 10 | D16: n-Hexane | E16: wt% | G16: 12.807537 | H16: 13.179385 | I16: 13.218187 | L16: n-Hexane | M16: wof% | N16: 14.268627 | O16: 10.91722
C17: 11 | D17: 2-Methyl Pentane | E17: wt% | G17: 8.3315921 | H17: 8.2272531 | I17: 8.2090946 | L17: 2-Methyl Pentane | M17: wof% | N17: 8.5874999 | O17: 9.6585235
C18: 12 | D18: 3-Methyl Pentane | E18: wt% | G18: 5.1643405 | H18: 5.0908527 | I18: 5.0318694 | L18: 3-Methyl Pentane | M18: wof% | N18: 5.1822401 | O18: 5.9866378
C19: 13 | D19: 2,3-Dimethyl Butane | E19: wt% | G19: 2.0601685 | H19: 2.0110633 | I19: 2.0163863 | L19: 2,3-Dimethyl Butane | M19: wof% | N19: 1.8746325 | O19: 2.9024668
... C29: 23 | D29: C8P | E29: wt% | G29: 11.888672 | H29: 12.510173 | I29: 11.337493 | L29: C8P | M29: wof% | N29: 4.9543986 | O29: 0.96430322
D30: Total → | E30: wt% | G30: =SUM(G7:G29) -> 100 | H30: =SUM(H7:H29) -> 100 | I30: =SUM(I7:I29) -> 100 | L30: C3 & Below | M30: wof% | N30: 0.017656294 | O30: 0.020180284
C31: 24 | D31: Isomerate RON → | E31: - | G31: 57.609735 | H31: 56.66822 | I31: 57.485621 | L31: C4-C5 Unknowns | M31: wof% | N31: 0 | O31: 0.0055362286
C32: 25 | D32: Isomerate MON → | E32: - | G32: 57.277669 | H32: 56.349075 | I32: 57.164756 | L32: C5-C6 Unknowns | M32: wof% | N32: 0 | O32: 0
L33: C6-C7 Unknowns | M33: wof% | N33: 0 | O33: 0
C34: 26 | D34: C5+ Yield | E34: wt% | G34: 94.854898 | H34: 95.711598 | I34: 94.567132 | L34: C7-C8 Unknowns | M34: wof% | N34: 0.05722763 | O34: 0.0074887693
C35: 27 | D35: C5+ Yield | E35: lv% | G35: 94.780044 | H35: 95.574233 | I35: 94.530978 | L35: Total | M35: wof% | N35: =SUM(N8:N34) -> 100.37053 | O35: 100.75026
C36: 28 | D36: C5+ product density | E36: g/cc | G36: 0.66802475 | H36: 0.66845694 | I36: 0.66775287
C37: 29 | D37: C5+ Isomearate MW | E37: g/g-mol | G37: 89.096223 | H37: 89.247524 | I37: 89.008908
C38: 30 | D38: H2 consumption | E38: Nm3/m3 | G38: 7.981205 | H38: 6.2000551 | I38: 8.4436787
C39: 31 | D39: Reid Vapour Pressure | E39: mbar | G39: 493.22053 | H39: 488.60222 | I39: 492.8252
C41: 32 | D41: ∆ RON (Prod - Feed) | E41: - | G41: =G31-44 -> 13.609735 | H41: =H31-44 -> 12.66822 | I41: =I31-44 -> 13.485621
C42: 33 | D42: ∆ MON (Prod - Feed) | E42: - | G42: =G32-43.9 -> 13.377669 | H42: =H32-43.9 -> 12.449075 | I42: =I32-43.9 -> 13.264756
C44: Simulation outuput - Operating Parameters
J45: Benefit USD/RON-BBL
C46: 34 | D46: Reactor Inlet Temp | E46: °C | G46: 211.65339 | H46: 212.80312 | I46: 201.45726 | J46: 1.25
C47: 35 | D47: Reactor Outlet Temp | E47: °C | G47: 224.1733 | H47: 223.59844 | I47: 214.27137
C48: 36 | D48: Reactor dT | E48: °C | G48: =G47-G46 -> 12.519908 | H48: =H47-H46 -> 10.795321 | I48: =I47-I46 -> 12.814106
C49: 37 | D49: WABT | E49: °C | G49: 220 | H49: 220 | I49: 220
C50: 38 | D50: Reactor Inlet Pre | E50: bar (g) | G50: 25 | H50: 25 | I50: 25
C51: 39 | D51: LHSV | E51: hr(-1) | G51: 1.4722119 | H51: 1.4757356 | I51: 1.4662483
C52: 40 | D52: WHSV | E52: hr(-1) | G52: 1.3904992 | H52: 1.980408 | I52: 1.5684832
C53: 41 | D53: H2:HC ratio | E53: mol:mol | G53: 3 | H53: 3 | I53: 3
...

Sheet Exp.Plan_Light Naphtha Isom.
A2: Objective | B2: Mononaphtha Upgrading is part of the Renewable Gasoline Theme within the Low Carbon Fuels Technology (LCF) Horizon 2 portfolio. This experimental program will generate the data required to support the SG1 decision planned for December 2026. The objective is to screen commercial isomerization catalysts based on: • Activity • Selectivity (minimizing hydrocracking and maximizing liquid yield C5+) • RON uplift The feedstock will be a commercial naphtha stream from Diamond Green Diesel (USA), produced via the HEFA/VO pathway. While catalyst stability is an important consideration, it is not included in the scope of this initial screening campaign. Based on the activity, selectivity, and RON uplift results, a decision will be made on whether catalyst stability should be evaluated in a subsequent study or as an extension of the current program.
A4: Catalyst Loading Plan | B4: Units | C4: Block 1 | G4: Block 2
A5: Reactor | B5: -- | C5: 1 | D5: 2 | E5: 3 | F5: 4 | G5: 5 | H5: 6 | I5: 7 | J5: 8
A6: SCI number | B6: -- | C6: 10684 | D6: 10910 | E6: 10685 | F6: -- | G6: 10684 | H6: 10910 | I6: 10685 | J6: --
A7: CISPRO label | B7: -- | C7: C530823 | D7: C569575 | E7: C530817 | F7: -- | G7: C530823 | H7: C569575 | I7: C530817 | J7: --
A8: Catalyst | B8: -- | C8: Z-700A | D8: ATHOS-1 | E8: ATHOS-3 | F8: SiC-INERT | G8: Z-700A | H8: ATHOS-1 | I8: ATHOS-3 | J8: SiC-INERT
A9: Shape & Size | B9: mm | C9: CY 1.6 | D9: CY 1.6 | E9: CY 1.6 | F9: 0.8mm | G9: CY 1.6 | H9: CY 1.6 | I9: CY 1.6 | J9: 0.8mm
A10: CBD (as-is) | B10: g/ml | C10: 0.7625 | D10: 0.5158 | E10: 0.6492 | F10: 1.77 | G10: 0.7625 | H10: 0.5158 | I10: 0.6492 | J10: 1.77
A11: LOI | B11: wt% | C11: 7.06 | D11: 3.33 | E11: 3.6 | F11: -- | G11: 7.06 | H11: 3.33 | I11: 3.6 | J11: --
A12: CBD (dry basis) | B12: g/ml | C12: =C10-(C10*(C11/100)) -> 0.7086675 | D12: =D10-(D10*(D11/100)) -> 0.49862386 | E12: =E10-(E10*(E11/100)) -> 0.6258288 | F12: -- | G12: =G10-(G10*(G11/100)) -> 0.7086675 | H12: =H10-(H10*(H11/100)) -> 0.49862386 | I12: =I10-(I10*(I11/100)) -> 0.6258288 | J12: --
A13: Catalyst volume | B13: ml | C13: 2 | D13: 2 | E13: 2 | F13: 2 | G13: 2 | H13: 2 | I13: 2 | J13: 2
A14: Catalyst amount | B14: gms | C14: =C13*C10 -> 1.525 | D14: =D13*D10 -> 1.0316 | E14: =E13*E10 -> 1.2984 | F14: =F13*F10 -> 3.54 | G14: =G13*G10 -> 1.525 | H14: =H13*H10 -> 1.0316 | I14: =I13*I10 -> 1.2984 | J14: =J13*J10 -> 3.54
A15: Naphtha Flow rate | B15: gms/hr | C15: =(C13*C22)*C27 -> 2.007 | D15: =C15 -> 2.007 | E15: =C15 -> 2.007 | F15: =C15 -> 2.007 | G15: =C15 -> 2.007 | H15: =C15 -> 2.007 | I15: =C15 -> 2.007 | J15: =C15 -> 2.007
A16: H2 Flow rate | B16: gms/hr | C16: =(C15/88.7)*$C$23*2 -> 0.13576099 | D16: =C16 -> 0.13576099 | E16: =C16 -> 0.13576099 | F16: =C16 -> 0.13576099 | G16: =C16 -> 0.13576099 | H16: =C16 -> 0.13576099 | I16: =C16 -> 0.13576099 | J16: =C16 -> 0.13576099
A17: H2 Flow rate | B17: NPLH | C17: =(C16/2)*22.4*(293/273) -> 1.6319167 | D17: =C17 -> 1.6319167 | E17: =D17 -> 1.6319167 | F17: =C17 -> 1.6319167 | G17: =C17 -> 1.6319167 | H17: =C17 -> 1.6319167 | I17: =C17 -> 1.6319167 | J17: =C17 -> 1.6319167
A19: Op.Conditions | B19: Units | C19: 1 | D19: 2 | E19: 3
A20: Pressure | B20: barg | C20: 25 | D20: 25 | E20: 25
A21: Temperature (*) | B21: oC | C21: 210 | D21: 220 | E21: 230
A22: LHSV | B22: h-1 | C22: 1.5 | D22: 1.5 | E22: 1.5
A23: H2/Naphtha | B23: mol.basis | C23: 3 | D23: 3 | E23: 3
A24: Duration | B24: hrs | C24: 72 | D24: 72 | E24: 72
A27: Feed Density @ 15 oC | B27: g/cc | C27: 0.669 | D27: To be updated following receipt of the analytical results
A28: Feed molecular weight | B28: -- | C28: 88.7 | D28: from offline DHA
A31: Naphtha/H2 | B31: mass ratio | C31: =(C15/C16) -> 14.783333
A61: H2 flow rate | B61: NLPH

Sheet Catalyst Loading Details
B4: Catalyst Loading Diagram | U4: Block1 | Z4: Block2
T5: Zones | U5: Reactor | Z5: Reactor
O6: Reactor ID | P6: mm | Q6: 4.4 | U6: 1 | V6: 2 | W6: 3 | X6: 4 | Z6: 5 | AA6: 6 | AB6: 7 | AC6: 8
G7: Empty space | O7: Isothermal zone height | P7: mm | Q7: 300 | T7: Catalyst | U7: Z-700A | V7: ATHOS-1 | W7: ATHOS-3 | X7: SiC | Z7: Z-700A | AA7: ATHOS-1 | AB7: ATHOS-3 | AC7: SiC
O8: Isothermal zone volume | P8: ml | Q8: =(22/28)*(Q6*Q6)*Q7/1000 -> 4.5634286 | T8: Preheating Zone, mm | U8: =930-50-U9-U10 -> 384 | V8: =930-50-V9-V10 -> 378 | W8: =930-50-W9-W10 -> 380 | Z8: =930-50-Z9-Z10 -> 380 | AA8: =930-50-AA9-AA10 -> 387 | AB8: =930-50-AB9-AB10 -> 386
G9: Preheating Zone SiC, 0.8 mm | O9: Catalyst volume | P9: ml | Q9: 2 | T9: Catalyst Bed Zone, mm | U9: 196 | V9: 202 | W9: 200 | Z9: 200 | AA9: 193 | AB9: 194
T10: Post Heating Zone, mm | U10: 300 | V10: 300 | W10: 300 | Z10: 300 | AA10: 300 | AB10: 300
G13: Z-700A, CY 1.6 (2 ml) + SiC 50 microns (2 ml) equally divided into 10 portions
G19: Post Heating Zone SiC, 0.8 mm
C27: Frit at the end of reactor bottom
C28: Height ~ 10 mm
C29: Size
AD57: =AD56*40 -> 0

Sheet Catalyst Drying and Reduction
A1: Steps | B1: Start Temperature | C1: Target Temperature | D1: Ramp Rate, oC/hr | E1: Holding, hrs | F1: N2 flow, NLPH | G1: H2 flow, NLPH | H1: Pressure, barg | I1: Remarks | L1: Step | M1: Time, hrs | N1: Cumulative Time, hrs | O1: Temperature, oC | P1: N2/H2 flow | Q1: N2/H2, barg
A2: 1 | B2: 25 | C2: =B2 -> 25 | D2: 0 | E2: 2 | F2: Y | H2: 1 | L2: 1 | M2: =(C2-B2) -> 0 | N2: 0 | O2: =B2 -> 25 | Q2: =H2 -> 1
A3: =A2+1 -> 2 | B3: 25 | C3: 300 | D3: 50 | E3: 2 | F3: Y | H3: 1 | M3: =E2 -> 2 | N3: =M3+N2 -> 2 | O3: =C2 -> 25 | Q3: =H2 -> 1
A4: =A3+1 -> 3 | B4: 300 | C4: 150 | D4: 50 | E4: 0 | F4: Y | H4: 1 | L4: 2 | M4: =(C3-B3)/D3 -> 5.5 | N4: =M4+N3 -> 7.5 | O4: =C3 -> 300 | Q4: =H3 -> 1
A5: =A4+1 -> 4 | B5: 150 | C5: 150 | D5: 0 | E5: 2 | G5: Y | H5: 1 | I5: Switch to H₂ gas and flush the system until N₂ is reduced to <0.5 vol%, confirm through online GC | M5: =E3 -> 2 | N5: =M5+N4 -> 9.5 | O5: =C3 -> 300 | Q5: =H3 -> 1
A6: =A5+1 -> 5 | B6: 150 | C6: 150 | D6: 0 | E6: 1 | G6: Y | H6: 5 | I6: Increase the reactor pressure from 1 to 5 barg | L6: 3 | M6: =(-C4+B4)/D4 -> 3 | N6: =M6+N5 -> 12.5 | O6: =C4 -> 150 | Q6: =H4 -> 1
A7: =A6+1 -> 6 | B7: 150 | C7: 300 | D7: 50 | E7: 2 | G7: Y | H7: 5 | M7: =E4 -> 0 | N7: =M7+N6 -> 12.5 | O7: =C4 -> 150 | Q7: =H4 -> 1
A8: =A7+1 -> 7 | B8: 300 | C8: 210 | D8: 50 | E8: 0 | G8: Y | H8: 5 | L8: 4 | M8: =(B5-C5) -> 0 | N8: =M8+N7 -> 12.5 | O8: =C5 -> 150 | Q8: 1 | R8: =I5 -> Switch to H₂ gas and flush the system until N₂ is reduced to <0.5 vol%, confirm through online GC
A9: =A8+1 -> 8 | B9: 210 | C9: 210 | D9: 0 | E9: 1 | G9: Y | H9: 25 | I9: Increase the H2 pressure to first operating pressure | M9: =E5 -> 2 | N9: =M9+N8 -> 14.5 | O9: =C5 -> 150 | Q9: =H5 -> 1
A10: =A9+1 -> 9 | B10: 210 | C10: 210 | D10: 0 | E10: 1 | G10: Y | H10: 25 | I10: Adjust H2 flow and introduce liquid feed as per condition 1 | L10: 5 | M10: =(B6-C6) -> 0 | N10: =M10+N9 -> 14.5 | O10: =C6 -> 150 | Q10: 1 | R10: Increase the reactor pressure from 1 to 5 barg
M11: =E6 -> 1 | N11: =M11+N10 -> 15.5 | O11: =C6 -> 150 | Q11: =H6 -> 5
L12: 6 | M12: =(C7-B7)/D7 -> 3 | N12: =M12+N11 -> 18.5 | O12: =C7 -> 300 | Q12: =H7 -> 5
M13: =E7 -> 2 | N13: =M13+N12 -> 20.5 | O13: =C7 -> 300 | Q13: =H7 -> 5
L14: 7 | M14: =(B8-C8)/D8 -> 1.8 | N14: =M14+N13 -> 22.3 | O14: =C8 -> 210 | Q14: =H8 -> 5
M15: =E8 -> 0 | N15: =M15+N14 -> 22.3 | O15: =C8 -> 210 | Q15: =H8 -> 5
L16: 8 | M16: =(B9-C9) -> 0 | N16: =M16+N15 -> 22.3 | O16: =C9 -> 210 | Q16: =H9 -> 25 | R16: Increase the H2 pressure to first operating pressure
M17: =E9 -> 1 | N17: =M17+N16 -> 23.3 | O17: =C9 -> 210 | Q17: =H9 -> 25
L18: 9 | M18: =(C10-B10) -> 0 | N18: =M18+N17 -> 23.3 | O18: =C10 -> 210 | Q18: =H10 -> 25
M19: =E10 -> 1 | N19: =M19+N18 -> 24.3 | O19: =C10 -> 210 | Q19: =H10 -> 25 | R19: Adjust H2 flow and introduce liquid feed as per experimental condition
I41: =50/60 -> 0.83333333

Sheet GC Calibration Data 
Q2: Below data generated on 7th Aug 2026
A4: 0 | H4: N2 | K4: H2 | Q4: H2 | T4: N2
F5: ter # | G5: Batch # | H5: Conc (Vol%) | I5: Area | J5: RF | K5: Conc (Vol%) | L5: Area | M5: RF | Q5: Conc (Vol%) | R5: Area | S5: RF | T5: Conc (Vol%) | U5: Area | V5: RF
F6: CAN-01 | G6: CFC2512006/30033552 | H6: 80.23 | I6: 442000000 | J6: 1.81317e-07 | K6: 19.77 | L6: 4556250 | M6: 4.3391e-06 | Q6: =100 -> 100 | R6: 17760614 | S6: 5.63044e-06 | T6: 100 | U6: 4.7723421e+08 | V6: 2.09541e-07
F7: CSL/16-17/SB3-207 | G7: CFC2512004/30035552 | H7: 60.13 | I7: 334000000 | J7: 1.80091e-07 | K7: 39.87 | L7: 9023977 | M7: 4.41823e-06 | Q7: 80.207 | R7: 14914676 | S7: 5.3501e-06 | T7: 95.23 | U7: 454519088 | V7: 2.09518e-07
F8: CSL/17-18/SB3/043 | G8: CFC2512005/30033552 | H8: 40.24 | I8: 229000000 | J8: 1.76049e-07 | K8: 59.76 | L8: 13285364 | M8: 4.49818e-06 | Q8: =15.79 -> 15.79 | R8: 2991265 | S8: 5.2787e-06 | T8: 83.93 | U8: 401984047 | V8: 2.08807e-07
F9: CSL/19-20/SB3/HP05 | G9: CFC2512008/300333552 | H9: 20.43 | I9: 125000000 | J9: 1.63839e-07 | K9: 79.57 | L9: 17515766 | M9: 4.54276e-06 | Q9: 4.77 | R9: 959013 | S9: 4.97386e-06 | T9: 9.63 | U9: 51061914 | V9: 1.88595e-07
J10: 1.75324e-07 | M10: 4.44957e-06
J16: Inter/Extra polation | K16: =-0.0000000000244761948*K17^2 + 0.00000000584415609*K17 + 0.00000423201041 -> 4.5716641e-06 | L16: Determined from Co-Pilot
J17: H2 | K17: 100
J30: Inter/Extra polation | K30: =1.07154555E-13*K31^3 - 0.0000000000231369299*K31^2 + 0.00000000170314458*K31 + 0.000000137948036 -> 1.6361339e-07 | L30: Determined from Co-Pilot
J31: N2 | K31: 20

Sheet H2+N2 Mixture Data
A1: Date/Time | B1: Sampled_reactor | C1: 10i1TIC02 | D1: 10i2TIC02 | E1: 10i1PIC01 | F1: 10i2PIC01 | G1: 01i14FIC01 | H1: 01i14FIC02 | I1: 01i14FIC03 | J1: 01i14FIC04 | K1: 01i14FIC05 | L1: 01i14FIC06 | M1: 01i14FIC07 | N1: 01i14FIC08 | O1: 01i14FI01 | P1: 10i1FIC01 | Q1: 10i1FIC02 | R1: 10i1FIC03 | S1: 10i1FIC04 | T1: 10i2FIC01 | U1: 10i2FIC02 | V1: 10i2FIC03 | W1: 10i2FIC04 | X1: 10i2TIC01 | Y1: 02i2FIC01 | Z1: 02i2FIC02 | AA1: 02i2FIC03 | AB1: 02i2FIC04 | AC1: 02i2FIC05 | AD1: 02i2FIC06 | AE1: 02i2FIC07 | AF1: 02i2FIC08 | AG1: GC Date/Time | AH1: Name_H2 | AI1: Conc_H2 | AJ1: ESTD_H2 | AK1: Area_H2 | AL1: RT_H2 | AN1: Date | AO1: Time Stamp | AQ1: Conc_N2 | AR1: ESTD_N2 | AS1: Area_N2 | AT1: RT_N2 | AV1: H2 flow, NLPH | AW1: H2 Flow, SLPH
A2: 15.08.2026 14:56:31 | B2: 1 | C2: 210 | D2: 210 | E2: 24.9378 | F2: 25.0391 | G2: 1721.97 | H2: 1722.65 | I2: 1722.03 | J2: 1722.87 | K2: 1722.25 | L2: 1721.96 | M2: 1722.29 | N2: 1722.12 | O2: 1.14695 | P2: 2499.72 | Q2: 2500.11 | R2: 2499.56 | S2: 2499.68 | T2: 2499.87 | U2: 2499.26 | V2: 2499.71 | W2: 1999.84 | X2: 210.1 | Y2: 0.0652975 | Z2: -0.0625165 | AA2: -0.0599337 | AB2: -0.00119883 | AC2: -0.0779806 | AD2: -0.0402661 | AE2: -0.058016 | AF2: -0.0732969 | AG2: 15.08.2026 15:02:36 | AH2: H2 | AI2: 35.56022 | AJ2: 36.22955 | AK2: 6434586 | AL2: 1.6183333 | AN2: =DATEVALUE(SUBSTITUTE(LEFT(A2,10),".","/")) -> 46249 | AO2: =TIMEVALUE(RIGHT(A2,8)) -> 0.62258102 | AQ2: 64.43978 | AR2: 65.652695 | AS2: 313316701 | AT2: 3.985 | AV2: =3.2/(AQ2/100)*(AI2/100) -> 1.7658767 | AW2: =AV2*273/293 -> 1.645339
A3: 15.08.2026 15:09:52 | B3: 2 | C3: 210 | D3: 210 | E3: 24.932 | F3: 25.0405 | G3: 1699.11 | H3: 1699.24 | I3: 1699.57 | J3: 1698.99 | K3: 1699.68 | L3: 1699.6 | M3: 1699.17 | N3: 1699.6 | O3: 1.20248 | P3: 2500.6 | Q3: 2499.93 | R3: 2499.85 | S3: 2500.82 | T3: 2500.19 | U3: 2499.53 | V3: 2500.99 | W3: 2000.27 | X3: 210.1 | Y3: 0.0660444 | Z3: -0.0613775 | AA3: -0.0651451 | AB3: -0.00212536 | AC3: -0.0769276 | AD3: -0.0372773 | AE3: -0.0609451 | AF3: -0.0715204 | AG3: 15.08.2026 15:15:58 | AH3: H2 | AI3: 37.414609 | AJ3: 37.681601 | AK3: 6692479 | AL3: 1.6166667 | AN3: =DATEVALUE(SUBSTITUTE(LEFT(A3,10),".","/")) -> 46249 | AO3: =TIMEVALUE(RIGHT(A3,8)) -> 0.63185185 | AQ3: 62.585391 | AR3: 63.032004 | AS3: 300809883 | AT3: 3.99 | AV3: =3.2/(AQ3/100)*(AI3/100) -> 1.9130143 | AW3: =AV3*273/293 -> 1.7824331
A4: 15.08.2026 15:23:14 | B4: 3 | C4: 210 | D4: 210 | E4: 24.9277 | F4: 25.0463 | G4: 1681.96 | H4: 1681.56 | I4: 1682.26 | J4: 1681.97 | K4: 1681.39 | L4: 1682.08 | M4: 1681.75 | N4: 1681.67 | O4: 1.17807 | P4: 2500.32 | Q4: 2498.98 | R4: 2499.76 | S4: 2499.78 | T4: 2500.2 | U4: 2500.8 | V4: 2499.68 | W4: 2000.31 | X4: 209.9 | Y4: 0.0625272 | Z4: -0.0655038 | AA4: -0.0610715 | AB4: 0.00141332 | AC4: -0.0831523 | AD4: -0.040555 | AE4: -0.0595964 | AF4: -0.0711781 | AG4: 15.08.2026 15:29:22 | AH4: H2 | AI4: 38.700399 | AJ4: 38.980274 | AK4: 6923131 | AL4: 1.6166667 | AN4: =DATEVALUE(SUBSTITUTE(LEFT(A4,10),".","/")) -> 46249 | AO4: =TIMEVALUE(RIGHT(A4,8)) -> 0.64113426 | AQ4: 61.299601 | AR4: 61.742909 | AS4: 294657891 | AT4: 3.99 | AV4: =3.2/(AQ4/100)*(AI4/100) -> 2.0202624 | AW4: =AV4*273/293 -> 1.8823605
A5: 15.08.2026 15:36:35 | B5: 4 | C5: 210 | D5: 210 | E5: 24.9219 | F5: 25.0333 | G5: 1721.55 | H5: 1721.62 | I5: 1721.56 | J5: 1721.17 | K5: 1721.55 | L5: 1721.76 | M5: 1722.17 | N5: 1721.33 | O5: 1.1273 | P5: 2500.02 | Q5: 2500.21 | R5: 2500.54 | S5: 2499.64 | T5: 2499.97 | U5: 2499.36 | V5: 2498.83 | W5: 2000.12 | X5: 209.8 | Y5: 0.0671284 | Z5: -0.0638513 | AA5: -0.062137 | AB5: -0.00341551 | AC5: -0.0824494 | AD5: -0.0398183 | AE5: -0.0590364 | AF5: -0.072072 | AG5: 15.08.2026 15:42:39 | AH5: H2 | AI5: 40.129555 | AJ5: 40.415839 | AK5: 7178096 | AL5: 1.6183333 | AN5: =DATEVALUE(SUBSTITUTE(LEFT(A5,10),".","/")) -> 46249 | AO5: =TIMEVALUE(RIGHT(A5,8)) -> 0.65040509 | AQ5: 59.870445 | AR5: 60.297559 | AS5: 287760196 | AT5: 3.993 | AV5: =3.2/(AQ5/100)*(AI5/100) -> 2.1448743 | AW5: =AV5*273/293 -> 1.9984665
A6: 15.08.2026 15:49:55 | B6: 5 | C6: 210 | D6: 210 | E6: 24.9841 | F6: 25.0116 | G6: 1689.77 | H6: 1689.41 | I6: 1688.99 | J6: 1690.4 | K6: 1688.92 | L6: 1689.52 | M6: 1688.86 | N6: 1688.41 | O6: 1.20062 | P6: 2498.33 | Q6: 2499.35 | R6: 2500.21 | S6: 2499.79 | T6: 2500.14 | U6: 2499.76 | V6: 2500.38 | W6: 1999.98 | X6: 210.1 | Y6: 0.0643429 | Z6: -0.0621697 | AA6: -0.058994 | AB6: 0.00347236 | AC6: -0.0803645 | AD6: -0.0399578 | AE6: -0.0576817 | AF6: -0.0692011 | AG6: 15.08.2026 15:56:01 | AH6: H2 | AI6: 40.177944 | AJ6: 40.434132 | AK6: 7181345 | AL6: 1.6183333 | AN6: =DATEVALUE(SUBSTITUTE(LEFT(A6,10),".","/")) -> 46249 | AO6: =TIMEVALUE(RIGHT(A6,8)) -> 0.65966435 | AQ6: 59.822056 | AR6: 60.203501 | AS6: 287311318 | AT6: 3.993 | AV6: =3.2/(AQ6/100)*(AI6/100) -> 2.1491976 | AW6: =AV6*273/293 -> 2.0024947
A7: 15.08.2026 16:03:16 | B7: 6 | C7: 210 | D7: 210 | E7: 24.9479 | F7: 25.026 | G7: 1710.71 | H7: 1710.96 | I7: 1709.6 | J7: 1710.9 | K7: 1710.54 | L7: 1710.63 | M7: 1709.89 | N7: 1710.07 | O7: 1.13661 | P7: 2500.03 | Q7: 2499.94 | R7: 2499.64 | S7: 2500.33 | T7: 2499.74 | U7: 2499.83 | V7: 2500.62 | W7: 2000.05 | X7: 209.9 | Y7: 0.0630507 | Z7: -0.0651824 | AA7: -0.061963 | AB7: -0.00151453 | AC7: -0.0794198 | AD7: -0.042287 | AE7: -0.0612475 | AF7: -0.0727909 | AG7: 15.08.2026 16:09:25 | AH7: H2 | AI7: 39.429741 | AJ7: 39.68851 | AK7: 7048918 | AL7: 1.6183333 | AN7: =DATEVALUE(SUBSTITUTE(LEFT(A7,10),".","/")) -> 46249 | AO7: =TIMEVALUE(RIGHT(A7,8)) -> 0.66893519 | AQ7: 60.570259 | AR7: 60.967769 | AS7: 290958662 | AT7: 3.992 | AV7: =3.2/(AQ7/100)*(AI7/100) -> 2.0831209 | AW7: =AV7*273/293 -> 1.9409283
A8: 15.08.2026 16:16:37 | B8: 7 | C8: 210 | D8: 210.1 | E8: 24.9566 | F8: 25.026 | G8: 1732.6 | H8: 1732.76 | I8: 1732.26 | J8: 1730.99 | K8: 1732 | L8: 1732.54 | M8: 1732.36 | N8: 1731.76 | O8: 1.09718 | P8: 2500.03 | Q8: 2499.88 | R8: 2500.28 | S8: 2500.06 | T8: 2499.77 | U8: 2500.6 | V8: 2500.31 | W8: 1999.6 | X8: 209.9 | Y8: 0.0591299 | Z8: -0.0676308 | AA8: -0.0643079 | AB8: -0.00335907 | AC8: -0.0848512 | AD8: -0.0438921 | AE8: -0.0670117 | AF8: -0.0728011 | AG8: 15.08.2026 16:22:42 | AH8: H2 | AI8: 40.09398 | AJ8: 40.357361 | AK8: 7167710 | AL8: 1.6183333 | AN8: =DATEVALUE(SUBSTITUTE(LEFT(A8,10),".","/")) -> 46249 | AO8: =TIMEVALUE(RIGHT(A8,8)) -> 0.67820602 | AQ8: 59.90602 | AR8: 60.299548 | AS8: 287769688 | AT8: 3.995 | AV8: =3.2/(AQ8/100)*(AI8/100) -> 2.1417002 | AW8: =AV8*273/293 -> 1.9955091
A9: 15.08.2026 16:29:58 | B9: 8 | C9: 210 | D9: 210 | E9: 24.9884 | F9: 25.0477 | G9: 1746.36 | H9: 1746.05 | I9: 1746.45 | J9: 1744.76 | K9: 1745.23 | L9: 1746.53 | M9: 1746.33 | N9: 1746.07 | O9: 1.11366 | P9: 2500.06 | Q9: 2500.11 | R9: 2499.31 | S9: 2500.31 | T9: 2500.07 | U9: 2499.23 | V9: 2499.54 | W9: 1999.8 | X9: 209.9 | Y9: 0.063555 | Z9: -0.0641136 | AA9: -0.0630302 | AB9: -0.000721554 | AC9: -0.0775981 | AD9: -0.039084 | AE9: -0.0647792 | AF9: -0.069991 | AG9: 15.08.2026 16:36:04 | AH9: H2 | AI9: 44.706396 | AJ9: 45.005458 | AK9: 7993240 | AL9: 1.6216667 | AN9: =DATEVALUE(SUBSTITUTE(LEFT(A9,10),".","/")) -> 46249 | AO9: =TIMEVALUE(RIGHT(A9,8)) -> 0.68747685 | AQ9: 55.293604 | AR9: 55.663488 | AS9: 265644853 | AT9: 3.998 | AV9: =3.2/(AQ9/100)*(AI9/100) -> 2.5872878 | AW9: =AV9*273/293 -> 2.4106811
A10: 15.08.2026 16:43:19 | B10: 1 | C10: 210 | D10: 210 | E10: 24.9638 | F10: 25.0477 | G10: 1726.7 | H10: 1726.1 | I10: 1726.66 | J10: 1725.29 | K10: 1726.62 | L10: 1726.76 | M10: 1726.44 | N10: 1726.99 | O10: 1.09068 | P10: 2498.58 | Q10: 2500.04 | R10: 2498.93 | S10: 2499.93 | T10: 2500.02 | U10: 2499.51 | V10: 2499.9 | W10: 1999.59 | X10: 209.9 | Y10: 0.0619934 | Z10: -0.0649598 | AA10: -0.0679281 | AB10: -0.00661796 | AC10: -0.080495 | AD10: -0.0419119 | AE10: -0.0620241 | AF10: -0.0739704 | AG10: 15.08.2026 16:49:24 | AH10: H2 | AI10: 40.864174 | AJ10: 41.164029 | AK10: 7310979 | AL10: 1.6200001 | AN10: =DATEVALUE(SUBSTITUTE(LEFT(A10,10),".","/")) -> 46249 | AO10: =TIMEVALUE(RIGHT(A10,8)) -> 0.69674769 | AQ10: 59.135826 | AR10: 59.569754 | AS10: 284286865 | AT10: 3.995 | AV10: =3.2/(AQ10/100)*(AI10/100) -> 2.2112713 | AW10: =AV10*273/293 -> 2.0603313
A11: 15.08.2026 16:56:40 | B11: 2 | C11: 210 | D11: 210 | E11: 25.1374 | F11: 25.0203 | G11: 1719.66 | H11: 1719.81 | I11: 1719.19 | J11: 1718.65 | K11: 1719 | L11: 1719.79 | M11: 1719.02 | N11: 1718.66 | O11: 1.15011 | P11: 2499.93 | Q11: 2500.55 | R11: 2500.14 | S11: 2499.66 | T11: 2499.5 | U11: 2499.21 | V11: 2500.21 | W11: 2000.63 | X11: 209.9 | Y11: 0.0621695 | Z11: -0.070568 | AA11: -0.0614616 | AB11: -0.00624094 | AC11: -0.0808944 | AD11: -0.0436409 | AE11: -0.0628531 | AF11: -0.0733058 | AG11: 15.08.2026 17:02:45 | AH11: H2 | AI11: 38.785206 | AJ11: 39.064077 | AK11: 6938015 | AL11: 1.6183333 | AN11: =DATEVALUE(SUBSTITUTE(LEFT(A11,10),".","/")) -> 46249 | AO11: =TIMEVALUE(RIGHT(A11,8)) -> 0.70601852 | AQ11: 61.214794 | AR11: 61.654937 | AS11: 294238060 | AT11: 3.99 | AV11: =3.2/(AQ11/100)*(AI11/100) -> 2.0274945 | AW11: =AV11*273/293 -> 1.889099
A12: 15.08.2026 17:10:02 | B12: 3 | C12: 210 | D12: 210.1 | E12: 25.1548 | F12: 25.0275 | G12: 1671.91 | H12: 1670.95 | I12: 1671.15 | J12: 1671.24 | K12: 1671.32 | L12: 1671.48 | M12: 1671.87 | N12: 1671.52 | O12: 1.20976 | P12: 2499.7 | Q12: 2500.44 | R12: 2499.83 | S12: 2499.94 | T12: 2499.95 | U12: 2500.07 | V12: 2500.42 | W12: 2000.03 | X12: 209.9 | Y12: 0.0660881 | Z12: -0.06438 | AA12: -0.0617342 | AB12: 0.000467063 | AC12: -0.078688 | AD12: -0.0392807 | AE12: -0.0614203 | AF12: -0.0710755 | AG12: 15.08.2026 17:16:07 | AH12: H2 | AI12: 39.031327 | AJ12: 39.333505 | AK12: 6985867 | AL12: 1.6166667 | AN12: =DATEVALUE(SUBSTITUTE(LEFT(A12,10),".","/")) -> 46249 | AO12: =TIMEVALUE(RIGHT(A12,8)) -> 0.71530093 | AQ12: 60.968673 | AR12: 61.440689 | AS12: 293215595 | AT12: 3.99 | AV12: =3.2/(AQ12/100)*(AI12/100) -> 2.0485971 | AW12: =AV12*273/293 -> 1.9087611
A13: 15.08.2026 17:23:22 | B13: 4 | C13: 210 | D13: 210 | E13: 25.0362 | F13: 25.0376 | G13: 1720.3 | H13: 1720.45 | I13: 1720.62 | J13: 1720.64 | K13: 1720.89 | L13: 1721.5 | M13: 1720.72 | N13: 1720.62 | O13: 1.13806 | P13: 2499.68 | Q13: 2499.85 | R13: 2499.7 | S13: 2500.46 | T13: 2500.04 | U13: 2499.98 | V13: 2498.56 | W13: 1999.51 | X13: 209.9 | Y13: 0.0624495 | Z13: -0.0629168 | AA13: -0.0608679 | AB13: -0.000927323 | AC13: -0.0798253 | AD13: -0.0378168 | AE13: -0.0637876 | AF13: -0.0721733 | AG13: 15.08.2026 17:29:28 | AH13: H2 | AI13: 40.488398 | AJ13: 40.810229 | AK13: 7248142 | AL13: 1.6183333 | AN13: =DATEVALUE(SUBSTITUTE(LEFT(A13,10),".","/")) -> 46249 | AO13: =TIMEVALUE(RIGHT(A13,8)) -> 0.72456019 | AQ13: 59.511602 | AR13: 59.984642 | AS13: 286266848 | AT13: 3.992 | AV13: =3.2/(AQ13/100)*(AI13/100) -> 2.1771028 | AW13: =AV13*273/293 -> 2.0284951
... A34: 15.08.2026 22:03:45 | B34: 1 | C34: 210 | D34: 210 | E34: 25.1085 | F34: 25.0203 | G34: 1451.93 | H34: 1451.84 | I34: 1451.51 | J34: 1451.42 | K34: 1452.04 | L34: 1453.67 | M34: 1452.68 | N34: 1453.07 | O34: 0.887657 | P34: 2500.03 | Q34: 2499.44 | R34: 2500.07 | S34: 2500.16 | T34: 2499.55 | U34: 2500.38 | V34: 2499.91 | W34: 2499.98 | X34: 210 | Y34: 0.0640244 | Z34: -0.065921 | AA34: -0.0595925 | AB34: 0.000563014 | AC34: -0.0768109 | AD34: -0.0411656 | AE34: -0.0631775 | AF34: -0.071592 | AG34: 15.08.2026 22:09:49 | AH34: H2 | AI34: 36.452102 | AJ34: 36.866629 | AK34: 6547735 | AL34: 1.6166667 | AN34: =DATEVALUE(SUBSTITUTE(LEFT(A34,10),".","/")) -> 46249 | AO34: =TIMEVALUE(RIGHT(A34,8)) -> 0.91927083 | AQ34: 63.547898 | AR34: 64.270554 | AS34: 306720659 | AT34: 3.983 | AV34: =3.2/(AQ34/100)*(AI34/100) -> 1.8355718 | AW34: =AV34*273/293 -> 1.7102768
A35: 15.08.2026 22:17:06 | B35: 2 | C35: 210 | D35: 210 | E35: 25.1548 | F35: 25.0318 | G35: 1416.66 | H35: 1416.74 | I35: 1416.59 | J35: 1417.6 | K35: 1417.22 | L35: 1417.09 | M35: 1416.89 | N35: 1416.74 | O35: 0.954568 | P35: 2500.78 | Q35: 2499.94 | R35: 2500.85 | S35: 2499.15 | T35: 2500.16 | U35: 2500.95 | V35: 2498.85 | W35: 2500.11 | X35: 210 | Y35: 0.0652198 | Z35: -0.0633594 | AA35: -0.0582151 | AB35: -0.000930614 | AC35: -0.0772955 | AD35: -0.0374277 | AE35: -0.0589886 | AF35: -0.0706181 | AG35: 15.08.2026 22:23:11 | AH35: H2 | AI35: 100 | AJ35: 35.073362 | AK35: 6229240 | AL35: 1.615 | AN35: =DATEVALUE(SUBSTITUTE(LEFT(A35,10),".","/")) -> 46249 | AO35: =TIMEVALUE(RIGHT(A35,8)) -> 0.92854167 | AQ35: 0 | AR35: 0 | AS35: 0 | AT35: 0 | AV35: =3.2/(AQ35/100)*(AI35/100) -> #DIV/0!
A36: 15.08.2026 22:30:26 | B36: 3 | C36: 210 | D36: 210 | E36: 25.1765 | F36: 25.0289 | G36: 1422.05 | H36: 1421.86 | I36: 1421.5 | J36: 1421.31 | K36: 1421.89 | L36: 1421.32 | M36: 1421.55 | N36: 1421.66 | O36: 0.896346 | P36: 2499.49 | Q36: 2499.91 | R36: 2499.67 | S36: 2500.21 | T36: 2500 | U36: 2499.71 | V36: 2500.53 | W36: 2500.1 | X36: 209.9 | Y36: 0.0628691 | Z36: -0.0658712 | AA36: -0.0582469 | AB36: -0.000346666 | AC36: -0.0787891 | AD36: -0.0377281 | AE36: -0.0580318 | AF36: -0.0682582 | AG36: 15.08.2026 22:36:36 | AH36: H2 | AI36: 34.818162 | AJ36: 35.213143 | AK36: 6254066 | AL36: 1.6166667 | AN36: =DATEVALUE(SUBSTITUTE(LEFT(A36,10),".","/")) -> 46249 | AO36: =TIMEVALUE(RIGHT(A36,8)) -> 0.93780093 | AQ36: 65.181838 | AR36: 65.921269 | AS36: 314598429 | AT36: 3.982 | AV36: =3.2/(AQ36/100)*(AI36/100) -> 1.709343 | AW36: =AV36*273/293 -> 1.5926643
A37: 15.08.2026 22:43:49 | B37: 4 | C37: 209.9 | D37: 210 | E37: 25.1519 | F37: 25.0203 | G37: 1407.86 | H37: 1408.06 | I37: 1407.55 | J37: 1407.57 | K37: 1407.41 | L37: 1407.77 | M37: 1408.07 | N37: 1407.63 | O37: 0.93023 | P37: 2500.42 | Q37: 2500.34 | R37: 2498.98 | S37: 2500.12 | T37: 2500.08 | U37: 2499.72 | V37: 2499.82 | W37: 2500.46 | X37: 210 | Y37: 0.0651273 | Z37: -0.0633413 | AA37: -0.0575899 | AB37: -0.00158498 | AC37: -0.0826805 | AD37: -0.0391003 | AE37: -0.0665161 | AF37: -0.0708663 | AG37: 15.08.2026 22:49:58 | AH37: H2 | AI37: 36.04887 | AJ37: 36.474052 | AK37: 6478011 | AL37: 1.615 | AN37: =DATEVALUE(SUBSTITUTE(LEFT(A37,10),".","/")) -> 46249 | AO37: =TIMEVALUE(RIGHT(A37,8)) -> 0.94709491 | AQ37: 63.95113 | AR37: 64.705409 | AS37: 308795936 | AT37: 3.982 | AV37: =3.2/(AQ37/100)*(AI37/100) -> 1.8038209 | AW37: =AV37*273/293 -> 1.6806932
A38: 15.08.2026 22:57:11 | B38: 5 | C38: 210.1 | D38: 210 | E38: 25.1939 | F38: 25.0289 | G38: 1430.31 | H38: 1430.5 | I38: 1430.48 | J38: 1430.19 | K38: 1430.33 | L38: 1430.49 | M38: 1430.5 | N38: 1429.8 | O38: 0.930645 | P38: 2498.56 | Q38: 2499.82 | R38: 2499.94 | S38: 2499.75 | T38: 2500.07 | U38: 2500.14 | V38: 2500.72 | W38: 2499.26 | X38: 209.9 | Y38: 0.0636339 | Z38: -0.0653769 | AA38: -0.0649995 | AB38: 0.00171304 | AC38: -0.0780465 | AD38: -0.0326063 | AE38: -0.0578281 | AF38: -0.0684567 | AG38: 15.08.2026 23:03:15 | AH38: H2 | AI38: 36.012061 | AJ38: 36.406842 | AK38: 6466074 | AL38: 1.615 | AN38: =DATEVALUE(SUBSTITUTE(LEFT(A38,10),".","/")) -> 46249 | AO38: =TIMEVALUE(RIGHT(A38,8)) -> 0.95637731 | AQ38: 63.987939 | AR38: 64.689404 | AS38: 308719556 | AT38: 3.98 | AV38: =3.2/(AQ38/100)*(AI38/100) -> 1.8009424 | AW38: =AV38*273/293 -> 1.6780112
A39: 15.08.2026 23:10:30 | B39: 6 | C39: 210 | D39: 210.1 | E39: 25.1968 | F39: 25.0391 | G39: 1415.14 | H39: 1414.5 | I39: 1414.8 | J39: 1414.69 | K39: 1415.26 | L39: 1414.08 | M39: 1414.52 | N39: 1414.66 | O39: 0.914323 | P39: 2498.83 | Q39: 2500.07 | R39: 2499.94 | S39: 2498.52 | T39: 2499.97 | U39: 2499 | V39: 2500.6 | W39: 2500.22 | X39: 209.8 | Y39: 0.0642314 | Z39: -0.0698975 | AA39: -0.0608962 | AB39: -0.00313263 | AC39: -0.0762175 | AD39: -0.0366476 | AE39: -0.074378 | AF39: -0.0692299 | AG39: 15.08.2026 23:16:35 | AH39: H2 | AI39: 35.123203 | AJ39: 35.513443 | AK39: 6307401 | AL39: 1.6166667 | AN39: =DATEVALUE(SUBSTITUTE(LEFT(A39,10),".","/")) -> 46249 | AO39: =TIMEVALUE(RIGHT(A39,8)) -> 0.965625 | AQ39: 64.876797 | AR39: 65.597616 | AS39: 313053846 | AT39: 3.982 | AV39: =3.2/(AQ39/100)*(AI39/100) -> 1.732426 | AW39: =AV39*273/293 -> 1.6141717
A40: 15.08.2026 23:23:51 | B40: 7 | C40: 210.1 | D40: 210.1 | E40: 25.1881 | F40: 25.0231 | G40: 1412.35 | H40: 1412.22 | I40: 1412.15 | J40: 1413.39 | K40: 1412.4 | L40: 1412.17 | M40: 1412.06 | N40: 1412.34 | O40: 0.959669 | P40: 2500.09 | Q40: 2500.6 | R40: 2499.81 | S40: 2500.25 | T40: 2499.25 | U40: 2499.6 | V40: 2499.77 | W40: 2500.46 | X40: 210.2 | Y40: 0.065282 | Z40: -0.0626377 | AA40: -0.0607869 | AB40: -0.00229383 | AC40: -0.0788046 | AD40: -0.0393944 | AE40: -0.0604748 | AF40: -0.0643816 | AG40: 15.08.2026 23:29:57 | AH40: H2 | AI40: 35.823931 | AJ40: 36.22495 | AK40: 6433769 | AL40: 1.615 | AN40: =DATEVALUE(SUBSTITUTE(LEFT(A40,10),".","/")) -> 46249 | AO40: =TIMEVALUE(RIGHT(A40,8)) -> 0.97489583 | AQ40: 64.176069 | AR40: 64.894466 | AS40: 309698179 | AT40: 3.982 | AV40: =3.2/(AQ40/100)*(AI40/100) -> 1.7862823 | AW40: =AV40*273/293 -> 1.6643518
A41: 15.08.2026 23:37:12 | B41: 8 | C41: 210 | D41: 210 | E41: 25.2271 | F41: 25.0318 | G41: 1404.25 | H41: 1404.1 | I41: 1405.23 | J41: 1405.21 | K41: 1405.05 | L41: 1404.85 | M41: 1404.2 | N41: 1404.58 | O41: 0.947817 | P41: 2499.55 | Q41: 2500.1 | R41: 2499.62 | S41: 2499.72 | T41: 2500.45 | U41: 2499.95 | V41: 2500.02 | W41: 2499.98 | X41: 209.9 | Y41: 0.0649649 | Z41: -0.0656954 | AA41: -0.0573854 | AB41: -0.00109171 | AC41: -0.0771943 | AD41: -0.0380661 | AE41: -0.0629641 | AF41: -0.0675948 | AG41: 15.08.2026 23:43:22 | AH41: H2 | AI41: 35.169522 | AJ41: 35.574657 | AK41: 6318273 | AL41: 1.6166667 | AN41: =DATEVALUE(SUBSTITUTE(LEFT(A41,10),".","/")) -> 46249 | AO41: =TIMEVALUE(RIGHT(A41,8)) -> 0.98416667 | AQ41: 64.830478 | AR41: 65.577293 | AS41: 312956857 | AT41: 3.98 | AV41: =3.2/(AQ41/100)*(AI41/100) -> 1.73595 | AW41: =AV41*273/293 -> 1.6174551
A42: 15.08.2026 23:50:35 | B42: 1 | C42: 210 | D42: 209.9 | E42: 25.1968 | F42: 25.0579 | G42: 1412.94 | H42: 1413.45 | I42: 1413.68 | J42: 1415.2 | K42: 1413.64 | L42: 1413.26 | M42: 1413.3 | N42: 1413.52 | O42: 0.956593 | P42: 2499.61 | Q42: 2500 | R42: 2500.68 | S42: 2499.92 | T42: 2500.15 | U42: 2499.96 | V42: 2499.94 | W42: 2500.53 | X42: 210 | Y42: 0.0593118 | Z42: -0.0633369 | AA42: -0.0616461 | AB42: -0.00791292 | AC42: -0.080852 | AD42: -0.0411257 | AE42: -0.0922889 | AF42: -0.0745808 | AG42: 15.08.2026 23:56:40 | AH42: H2 | AI42: 36.496474 | AJ42: 36.897264 | AK42: 6553176 | AL42: 1.6166667 | AN42: =DATEVALUE(SUBSTITUTE(LEFT(A42,10),".","/")) -> 46249 | AO42: =TIMEVALUE(RIGHT(A42,8)) -> 0.99346065 | AQ42: 63.503526 | AR42: 64.200898 | AS42: 306388239 | AT42: 3.98 | AV42: =3.2/(AQ42/100)*(AI42/100) -> 1.8390903 | AW42: =AV42*273/293 -> 1.7135551
A43: 16.08.2026 00:03:56 | B43: 2 | C43: 210 | D43: 210 | E43: 25.2228 | F43: 25.0391 | G43: 1418.62 | H43: 1418.9 | I43: 1418.63 | J43: 1416.69 | K43: 1418.22 | L43: 1417.43 | M43: 1417.91 | N43: 1418.06 | O43: 0.885036 | P43: 2499.93 | Q43: 2500.26 | R43: 2499.97 | S43: 2500.11 | T43: 2499.98 | U43: 2499.7 | V43: 2499.4 | W43: 2500.55 | X43: 210 | Y43: 0.0660196 | Z43: -0.063692 | AA43: -0.0600164 | AB43: -0.00154234 | AC43: -0.0759315 | AD43: -0.0374478 | AE43: -0.0707937 | AF43: -0.0699965 | AG43: 16.08.2026 00:10:05 | AH43: H2 | AI43: 100 | AJ43: 34.992059 | AK43: 6214800 | AL43: 1.615 | AN43: =DATEVALUE(SUBSTITUTE(LEFT(A43,10),".","/")) -> 46250 | AO43: =TIMEVALUE(RIGHT(A43,8)) -> 0.0027314815 | AQ43: 0 | AR43: 0 | AS43: 0 | AT43: 0 | AV43: =3.2/(AQ43/100)*(AI43/100) -> #DIV/0! | AW43: =AV43*273/293 -> #DIV/0!
A44: 16.08.2026 00:17:17 | B44: 3 | C44: 210 | D44: 210 | E44: 25.2402 | F44: 25.0275 | G44: 1434.96 | H44: 1435.88 | I44: 1435.51 | J44: 1434.81 | K44: 1436.08 | L44: 1435.84 | M44: 1436.24 | N44: 1436.39 | O44: 0.948814 | P44: 2499.3 | Q44: 2500.26 | R44: 2499.62 | S44: 2500.09 | T44: 2499.8 | U44: 2499.99 | V44: 2499.5 | W44: 2500.38 | X44: 210.1 | Y44: 0.0655745 | Z44: -0.0635258 | AA44: -0.0584998 | AB44: 0.00114854 | AC44: -0.0792895 | AD44: -0.0382409 | AE44: -0.0942294 | AF44: -0.073889 | AG44: 16.08.2026 00:23:21 | AH44: H2 | AI44: 34.913508 | AJ44: 35.301181 | AK44: 6269702 | AL44: 1.6166667 | AN44: =DATEVALUE(SUBSTITUTE(LEFT(A44,10),".","/")) -> 46250 | AO44: =TIMEVALUE(RIGHT(A44,8)) -> 0.012002315 | AQ44: 65.086492 | AR44: 65.8092 | AS44: 314063594 | AT44: 3.98 | AV44: =3.2/(AQ44/100)*(AI44/100) -> 1.7165348 | AW44: =AV44*273/293 -> 1.5993651
A45: 16.08.2026 00:30:38 | B45: 4 | C45: 210 | D45: 210 | E45: 25.2648 | F45: 25.0101 | G45: 1444.48 | H45: 1444.62 | I45: 1444.25 | J45: 1445.25 | K45: 1443.76 | L45: 1444.46 | M45: 1444.35 | N45: 1444.44 | O45: 0.920554 | P45: 2499.64 | Q45: 2499.3 | R45: 2499.08 | S45: 2500.02 | T45: 2500.35 | U45: 2499.45 | V45: 2499.77 | W45: 2501.31 | X45: 209.9 | Y45: 0.0624593 | Z45: -0.0661445 | AA45: -0.0614515 | AB45: -8.01398e-05 | AC45: -0.077938 | AD45: -0.0398052 | AE45: -0.108166 | AF45: -0.0757631 | AG45: 16.08.2026 00:36:43 | AH45: H2 | AI45: 35.99978 | AJ45: 36.386825 | AK45: 6462519 | AL45: 1.615 | AN45: =DATEVALUE(SUBSTITUTE(LEFT(A45,10),".","/")) -> 46250 | AO45: =TIMEVALUE(RIGHT(A45,8)) -> 0.021273148 | AQ45: 64.00022 | AR45: 64.688307 | AS45: 308714317 | AT45: 3.98 | AV45: =3.2/(AQ45/100)*(AI45/100) -> 1.7999828 | AW45: =AV45*273/293 -> 1.6771171
A46: 16.08.2026 00:43:59 | B46: 5 | C46: 210 | D46: 210.1 | E46: 25.217 | F46: 25.0203 | G46: 1423.51 | H46: 1423.56 | I46: 1423.35 | J46: 1423.89 | K46: 1423.61 | L46: 1423.44 | M46: 1422.98 | N46: 1423.12 | O46: 0.939699 | P46: 2500.08 | Q46: 2500.03 | R46: 2499.78 | S46: 2499.1 | T46: 2499.67 | U46: 2500.18 | V46: 2500.94 | W46: 2500.32 | X46: 210.1 | Y46: 0.0662206 | Z46: -0.0627123 | AA46: -0.0571915 | AB46: -0.00334093 | AC46: -0.0811581 | AD46: -0.0371482 | AE46: -0.084135 | AF46: -0.0708623 | AG46: 16.08.2026 00:50:04 | AH46: H2 | AI46: 36.108971 | AJ46: 36.494243 | AK46: 6481597 | AL46: 1.615 | AN46: =DATEVALUE(SUBSTITUTE(LEFT(A46,10),".","/")) -> 46250 | AO46: =TIMEVALUE(RIGHT(A46,8)) -> 0.030543981 | AQ46: 63.891029 | AR46: 64.572728 | AS46: 308162736 | AT46: 3.98 | AV46: =3.2/(AQ46/100)*(AI46/100) -> 1.8085279 | AW46: =AV46*273/293 -> 1.6850789
A47: 16.08.2026 00:57:20 | B47: 6 | C47: 210 | D47: 210 | E47: 25.2836 | F47: 25.0116 | G47: 1456.26 | H47: 1457.03 | I47: 1456.7 | J47: 1457.33 | K47: 1456.52 | L47: 1456.55 | M47: 1456.51 | N47: 1456.78 | O47: 0.894632 | P47: 2500.16 | Q47: 2499.99 | R47: 2500.19 | S47: 2499.19 | T47: 2500.24 | U47: 2499.07 | V47: 2500.31 | W47: 2499.85 | X47: 210 | Y47: 0.0633099 | Z47: -0.06221 | AA47: -0.0614199 | AB47: 0.000884914 | AC47: -0.0797331 | AD47: -0.0386274 | AE47: -0.0811457 | AF47: -0.0706111 | AG47: 16.08.2026 01:03:24 | AH47: H2 | AI47: 35.203222 | AJ47: 35.586549 | AK47: 6320385 | AL47: 1.615 | AN47: =DATEVALUE(SUBSTITUTE(LEFT(A47,10),".","/")) -> 46250 | AO47: =TIMEVALUE(RIGHT(A47,8)) -> 0.039814815 | AQ47: 64.796778 | AR47: 65.502349 | AS47: 312599200 | AT47: 3.98 | AV47: =3.2/(AQ47/100)*(AI47/100) -> 1.7385172 | AW47: =AV47*273/293 -> 1.619847
... A55: 16.08.2026 02:44:07 | B55: 6 | C55: 210 | D55: 210 | E55: 25.3733 | F55: 25.0333 | G55: 1398.57 | H55: 1398.69 | I55: 1398.36 | J55: 1397.84 | K55: 1398.22 | L55: 1398.03 | M55: 1398.59 | N55: 1398.32 | O55: 0.913814 | P55: 2499.91 | Q55: 2499.95 | R55: 2499.85 | S55: 2499.78 | T55: 2500.37 | U55: 2499.85 | V55: 2499.81 | W55: 2499.8 | X55: 209.9 | Y55: 0.0643803 | Z55: -0.0647219 | AA55: -0.0552293 | AB55: -0.00240015 | AC55: -0.0814193 | AD55: -0.0374477 | AE55: -0.071061 | AF55: -0.065711 | AG55: 16.08.2026 02:50:15 | AH55: H2 | AI55: 100 | AJ55: 35.547513 | AK55: 6313452 | AL55: 1.615 | AN55: =DATEVALUE(SUBSTITUTE(LEFT(A55,10),".","/")) -> 46250 | AO55: =TIMEVALUE(RIGHT(A55,8)) -> 0.11396991 | AQ55: 0 | AR55: 0 | AS55: 0 | AT55: 0 | AV55: =3.2/(AQ55/100)*(AI55/100) -> #DIV/0! | AW55: =AV55*273/293 -> #DIV/0!
A56: 16.08.2026 02:57:28 | B56: 7 | C56: 209.9 | D56: 210 | E56: 25.3443 | F56: 25.0391 | G56: 1416.17 | H56: 1415.74 | I56: 1416.21 | J56: 1415.68 | K56: 1415.84 | L56: 1415.47 | M56: 1416.36 | N56: 1415.52 | O56: 0.95459 | P56: 2499.67 | Q56: 2500.03 | R56: 2500.44 | S56: 2500.36 | T56: 2499.46 | U56: 2499.93 | V56: 2500.22 | W56: 2500 | X56: 210 | Y56: 0.0692035 | Z56: -0.063024 | AA56: -0.0553455 | AB56: 0.00402329 | AC56: -0.0785202 | AD56: -0.0373573 | AE56: -0.0664344 | AF56: -0.0652578 | AG56: 16.08.2026 03:03:32 | AH56: H2 | AI56: 35.788842 | AJ56: 36.131637 | AK56: 6417196 | AL56: 1.615 | AN56: =DATEVALUE(SUBSTITUTE(LEFT(A56,10),".","/")) -> 46250 | AO56: =TIMEVALUE(RIGHT(A56,8)) -> 0.12324074 | AQ56: 64.211158 | AR56: 64.826191 | AS56: 309372346 | AT56: 3.98
A57: 16.08.2026 03:10:49 | B57: 8 | C57: 210 | D57: 209.9 | E57: 25.2575 | F57: 25.0275 | G57: 1386.95 | H57: 1386.48 | I57: 1386.59 | J57: 1384.96 | K57: 1386.56 | L57: 1385.87 | M57: 1386.56 | N57: 1386.31 | O57: 0.970284 | P57: 2500.46 | Q57: 2499.85 | R57: 2500.87 | S57: 2499.53 | T57: 2500.27 | U57: 2499.98 | V57: 2500.22 | W57: 2500.07 | X57: 209.8 | Y57: 0.0638362 | Z57: -0.0656246 | AA57: -0.0585122 | AB57: -0.00169305 | AC57: -0.0782012 | AD57: -0.040457 | AE57: -0.0599287 | AF57: -0.0686923 | AG57: 16.08.2026 03:16:53 | AH57: H2 | AI57: 100 | AJ57: 35.555266 | AK57: 6314829 | AL57: 1.6166667 | AN57: =DATEVALUE(SUBSTITUTE(LEFT(A57,10),".","/")) -> 46250 | AO57: =TIMEVALUE(RIGHT(A57,8)) -> 0.13251157 | AQ57: 0 | AR57: 0 | AS57: 0 | AT57: 0
A58: 16.08.2026 03:24:10 | B58: 1 | C58: 209.9 | D58: 210 | E58: 25.2416 | F58: 25.0333 | G58: 1430.12 | H58: 1429.71 | I58: 1429.41 | J58: 1431.02 | K58: 1429.93 | L58: 1429.8 | M58: 1429.36 | N58: 1429.31 | O58: 0.913718 | P58: 2500 | Q58: 2499.86 | R58: 2500.24 | S58: 2499.53 | T58: 2499.84 | U58: 2499.77 | V58: 2501.06 | W58: 2500.07 | X58: 210.1 | Y58: 0.0660672 | Z58: -0.0649148 | AA58: -0.0566545 | AB58: 0.000326567 | AC58: -0.0767074 | AD58: -0.0392528 | AE58: -0.055781 | AF58: -0.0667719 | AG58: 16.08.2026 03:30:19 | AH58: H2 | AI58: 100 | AJ58: 36.93201 | AK58: 6559347 | AL58: 1.615 | AN58: =DATEVALUE(SUBSTITUTE(LEFT(A58,10),".","/")) -> 46250 | AO58: =TIMEVALUE(RIGHT(A58,8)) -> 0.14178241 | AQ58: 0 | AR58: 0 | AS58: 0 | AT58: 0
A59: 16.08.2026 03:37:32 | B59: 2 | C59: 209.9 | D59: 210 | E59: 25.1013 | F59: 25.0159 | G59: 1407.23 | H59: 1407.09 | I59: 1406.12 | J59: 1403.83 | K59: 1406.05 | L59: 1407.32 | M59: 1406.82 | N59: 1407.63 | O59: 0.881199 | P59: 2500.17 | Q59: 2499.42 | R59: 2499.32 | S59: 2499.58 | T59: 2500.08 | U59: 2499.7 | V59: 2498.58 | W59: 2500.55 | X59: 209.7 | Y59: 0.0640018 | Z59: -0.0612342 | AA59: -0.05996 | AB59: 0.0019466 | AC59: -0.0796666 | AD59: -0.0357355 | AE59: -0.0526158 | AF59: -0.0667025 | AG59: 16.08.2026 03:43:40 | AH59: H2 | AI59: 100 | AJ59: 35.292516 | AK59: 6268163 | AL59: 1.6166667 | AN59: =DATEVALUE(SUBSTITUTE(LEFT(A59,10),".","/")) -> 46250 | AO59: =TIMEVALUE(RIGHT(A59,8)) -> 0.15106481 | AQ59: 0 | AR59: 0 | AS59: 0 | AT59: 0
A60: 16.08.2026 03:50:53 | B60: 3 | C60: 210 | D60: 210 | E60: 25.0622 | F60: 25.0318 | G60: 1438.6 | H60: 1439.19 | I60: 1439.4 | J60: 1439.83 | K60: 1439.2 | L60: 1438.34 | M60: 1438.67 | N60: 1438.48 | O60: 0.915402 | P60: 2500.1 | Q60: 2499.57 | R60: 2499.37 | S60: 2499.25 | T60: 2500.43 | U60: 2499.64 | V60: 2499.75 | W60: 2500.56 | X60: 209.9 | Y60: 0.0654283 | Z60: -0.0619496 | AA60: -0.0559086 | AB60: -0.00517018 | AC60: -0.0781128 | AD60: -0.0382084 | AE60: -0.0624172 | AF60: -0.066334 | AG60: 16.08.2026 03:56:58 | AH60: H2 | AI60: 100 | AJ60: 35.532491 | AK60: 6310784 | AL60: 1.6166667 | AN60: =DATEVALUE(SUBSTITUTE(LEFT(A60,10),".","/")) -> 46250 | AO60: =TIMEVALUE(RIGHT(A60,8)) -> 0.16033565 | AQ60: 0 | AR60: 0 | AS60: 0 | AT60: 0
A61: 16.08.2026 04:04:13 | B61: 4 | C61: 210 | D61: 209.9 | E61: 25.1071 | F61: 25.0159 | G61: 1434.48 | H61: 1434.51 | I61: 1434.3 | J61: 1434.15 | K61: 1434.26 | L61: 1434.83 | M61: 1433.92 | N61: 1433.66 | O61: 0.877565 | P61: 2499.39 | Q61: 2500.03 | R61: 2499.88 | S61: 2500.15 | T61: 2499.99 | U61: 2499.52 | V61: 2499.97 | W61: 2500.06 | X61: 210.1 | Y61: 0.0631401 | Z61: -0.0597379 | AA61: -0.0547182 | AB61: -0.00114969 | AC61: -0.0787305 | AD61: -0.0335804 | AE61: -0.0743909 | AF61: -0.0661057 | AG61: 16.08.2026 04:10:19 | AH61: H2 | AI61: 100 | AJ61: 36.463225 | AK61: 6476088 | AL61: 1.615 | AN61: =DATEVALUE(SUBSTITUTE(LEFT(A61,10),".","/")) -> 46250 | AO61: =TIMEVALUE(RIGHT(A61,8)) -> 0.16959491 | AQ61: 0 | AR61: 0 | AS61: 0 | AT61: 0
A62: 16.08.2026 04:17:34 | B62: 5 | C62: 210 | D62: 210 | E62: 25.0477 | F62: 25.0289 | G62: 1448.35 | H62: 1448.25 | I62: 1448.9 | J62: 1449.59 | K62: 1448.77 | L62: 1449.34 | M62: 1449.16 | N62: 1449.21 | O62: 0.955463 | P62: 2500.08 | Q62: 2500.18 | R62: 2500.05 | S62: 2499.73 | T62: 2499.94 | U62: 2499.77 | V62: 2500.22 | W62: 2500.39 | X62: 210.2 | Y62: 0.0637853 | Z62: -0.0682151 | AA62: -0.0624039 | AB62: -0.00075493 | AC62: -0.0755966 | AD62: -0.0366724 | AE62: -0.0675623 | AF62: -0.0697415 | AG62: 16.08.2026 04:23:40 | AH62: H2 | AI62: 100 | AJ62: 36.381843 | AK62: 6461634 | AL62: 1.615 | AN62: =DATEVALUE(SUBSTITUTE(LEFT(A62,10),".","/")) -> 46250 | AO62: =TIMEVALUE(RIGHT(A62,8)) -> 0.17886574 | AQ62: 0 | AR62: 0 | AS62: 0 | AT62: 0
A63: 16.08.2026 04:30:55 | B63: 6 | C63: 210 | D63: 210 | E63: 25.0984 | F63: 25.0231 | G63: 1426.21 | H63: 1425.73 | I63: 1426.06 | J63: 1424.9 | K63: 1425.58 | L63: 1425.53 | M63: 1426.25 | N63: 1426.15 | O63: 0.850312 | P63: 2499.93 | Q63: 2500.33 | R63: 2499.52 | S63: 2500.22 | T63: 2499.97 | U63: 2500.13 | V63: 2499.35 | W63: 2500.2 | X63: 209.9 | Y63: 0.0639846 | Z63: -0.0629017 | AA63: -0.055252 | AB63: -0.00383018 | AC63: -0.0778758 | AD63: -0.0356248 | AE63: -0.0635069 | AF63: -0.0683153 | AG63: 16.08.2026 04:37:03 | AH63: H2 | AI63: 100 | AJ63: 35.504969 | AK63: 6305896 | AL63: 1.615 | AN63: =DATEVALUE(SUBSTITUTE(LEFT(A63,10),".","/")) -> 46250 | AO63: =TIMEVALUE(RIGHT(A63,8)) -> 0.18813657 | AQ63: 0 | AR63: 0 | AS63: 0 | AT63: 0
A64: 16.08.2026 04:44:16 | B64: 7 | C64: 210 | D64: 210 | E64: 25.1042 | F64: 25.0347 | G64: 1429.39 | H64: 1429.49 | I64: 1429.81 | J64: 1429.3 | K64: 1428.75 | L64: 1429.16 | M64: 1429.74 | N64: 1428.7 | O64: 0.879672 | P64: 2499.89 | Q64: 2500.58 | R64: 2500.16 | S64: 2499.93 | T64: 2500.25 | U64: 2500.18 | V64: 2499.35 | W64: 2501.13 | X64: 210 | Y64: 0.0654372 | Z64: -0.0612109 | AA64: -0.0573913 | AB64: -0.00211125 | AC64: -0.0800737 | AD64: -0.036318 | AE64: -0.0652149 | AF64: -0.0698554 | AG64: 16.08.2026 04:50:25 | AH64: H2 | AI64: 35.935392 | AJ64: 36.274442 | AK64: 6442559 | AL64: 1.6166667 | AN64: =DATEVALUE(SUBSTITUTE(LEFT(A64,10),".","/")) -> 46250 | AO64: =TIMEVALUE(RIGHT(A64,8)) -> 0.19740741 | AQ64: 64.064608 | AR64: 64.669056 | AS64: 308622447 | AT64: 3.98
A65: 16.08.2026 04:57:37 | B65: 8 | C65: 210 | D65: 210 | E65: 25.1562 | F65: 25.0231 | G65: 1452.71 | H65: 1452.66 | I65: 1452.25 | J65: 1452.33 | K65: 1452.03 | L65: 1452.78 | M65: 1452.5 | N65: 1452.4 | O65: 0.945372 | P65: 2501.01 | Q65: 2499.76 | R65: 2499.45 | S65: 2499.53 | T65: 2500.33 | U65: 2499.62 | V65: 2499.18 | W65: 2500.21 | X65: 210.1 | Y65: 0.0629409 | Z65: -0.0646117 | AA65: -0.0582379 | AB65: -0.00441517 | AC65: -0.0831115 | AD65: -0.0410171 | AE65: -0.0615066 | AF65: -0.0703405 | AG65: 16.08.2026 05:03:47 | AH65: H2 | AI65: 100 | AJ65: 35.621964 | AK65: 6326675 | AL65: 1.615 | AN65: =DATEVALUE(SUBSTITUTE(LEFT(A65,10),".","/")) -> 46250 | AO65: =TIMEVALUE(RIGHT(A65,8)) -> 0.20667824 | AQ65: 0 | AR65: 0 | AS65: 0 | AT65: 0
A66: 16.08.2026 05:10:59 | B66: 1 | C66: 210.1 | D66: 210.1 | E66: 25.2141 | F66: 25.0217 | G66: 1416.99 | H66: 1416.74 | I66: 1416.15 | J66: 1417.03 | K66: 1416.73 | L66: 1416.22 | M66: 1416.85 | N66: 1416.57 | O66: 0.953559 | P66: 2499.3 | Q66: 2499.79 | R66: 2500.01 | S66: 2499.52 | T66: 2499.64 | U66: 2499.22 | V66: 2499.88 | W66: 2499.44 | X66: 209.8 | Y66: 0.0668619 | Z66: -0.0652807 | AA66: -0.0572853 | AB66: 0.00295775 | AC66: -0.0779099 | AD66: -0.0367203 | AE66: -0.0608646 | AF66: -0.0687419 | AG66: 16.08.2026 05:17:09 | AH66: H2 | AI66: 100 | AJ66: 36.894764 | AK66: 6552732 | AL66: 1.6166667 | AN66: =DATEVALUE(SUBSTITUTE(LEFT(A66,10),".","/")) -> 46250 | AO66: =TIMEVALUE(RIGHT(A66,8)) -> 0.21596065 | AQ66: 0 | AR66: 0 | AS66: 0 | AT66: 0
A67: 16.08.2026 05:24:22 | B67: 2 | C67: 210 | D67: 210 | E67: 25.2402 | F67: 25.0087 | G67: 1461.7 | H67: 1461.2 | I67: 1461.23 | J67: 1461.12 | K67: 1461.11 | L67: 1461.29 | M67: 1461.65 | N67: 1461.19 | O67: 0.872703 | P67: 2500.13 | Q67: 2500.41 | R67: 2499.91 | S67: 2500.26 | T67: 2499.67 | U67: 2499.04 | V67: 2499.82 | W67: 2498.94 | X67: 209.9 | Y67: 0.062597 | Z67: -0.0641749 | AA67: -0.0571283 | AB67: -0.00300302 | AC67: -0.0806891 | AD67: -0.0406204 | AE67: -0.0627281 | AF67: -0.0704321 | AG67: 16.08.2026 05:30:26 | AH67: H2 | AI67: 100 | AJ67: 35.052209 | AK67: 6225483 | AL67: 1.6166667 | AN67: =DATEVALUE(SUBSTITUTE(LEFT(A67,10),".","/")) -> 46250 | AO67: =TIMEVALUE(RIGHT(A67,8)) -> 0.22525463 | AQ67: 0 | AR67: 0 | AS67: 0 | AT67: 0
...

Sheet Raw Data
A1: Date/Time | B1: Sampled_reactor | C1: 10i1TIC02 | D1: 10i2TIC02 | E1: 10i1PIC01 | F1: 10i2PIC01 | G1: 01i14FIC01 | H1: 01i14FIC02 | I1: 01i14FIC03 | J1: 01i14FIC04 | K1: 01i14FIC05 | L1: 01i14FIC06 | M1: 01i14FIC07 | N1: 01i14FIC08 | O1: 01i14FI01 | P1: 10i1FIC01 | Q1: 10i1FIC02 | R1: 10i1FIC03 | S1: 10i1FIC04 | T1: 10i2FIC01 | U1: 10i2FIC02 | V1: 10i2FIC03 | W1: 10i2FIC04 | X1: 10i2TIC01 | Y1: 02i2FIC01 | Z1: 02i2FIC02 | AA1: 02i2FIC03 | AB1: 02i2FIC04 | AC1: 02i2FIC05 | AD1: 02i2FIC06 | AE1: 02i2FIC07 | AF1: 02i2FIC08 | AG1: GC Date/Time | AH1: Name_H2 | AI1: Conc_H2 | AJ1: ESTD_H2 | AK1: Area_H2 | AL1: RT_H2 | AM1: Conc_N2 | AN1: ESTD_N2 | AO1: Area_N2 | AP1: RT_N2 | AU1: Date | AV1: Time Stamp | AW1: GC Data | AX1: GC Time Stamp | BB1: Methane | BC1: Ethane | BD1: Propane | BE1: n-Butane | BF1: iso-Butane | BG1: n-Pentane | BH1: iso-Pentane | BI1: Cyclopentane | BJ1: n-Hexane | BK1: 2-Methyl Pentane | BL1: 3-Methyl Pentane | BM1: 2,3-Dimethyl Butane | BN1: 2,2-Dimethyl Butane | BO1: Cyclohexane | BP1: Methyl Cyclopentane | BQ1: Benzene | BR1: n-Heptane | BS1: iC7 Single Branched | BT1: iC7 Multi Branched | BU1: C7N | BV1: Toluene | BW1: C8P | BX1: C8N | BY1: C8A | BZ1: C9P | CA1: C9N | CB1: C9A | CC1: C10P | CD1: C10N | CE1: C10A | CF1: C3 & Below | CG1: C4-C5 Unknowns | CH1: C5-C6 Unknowns | CI1: C6-C7 Unknowns | CJ1: C7-C8 Unknowns | CK1: C8 Plus | CL1: Carbon | CM1: Hydrogen | CN1: Linear RON | CO1: Calculated RON | CP1: Molecular Weight | CQ1: Specific Gravity | CR1: Remarks | EH1: Mol. Weight | EI1: Carbon, wt% | EJ1: Hydrogen, wt% | EK1: RON
A2: 14.08.2026 21:36:45 | B2: 1 | C2: 210.1 | D2: 210 | E2: 25.0825 | F2: 25.0506 | G2: 1685.88 | H2: 1686.14 | I2: 1686.11 | J2: 1686.89 | K2: 1685.24 | L2: 1685.76 | M2: 1685.08 | N2: 1685.35 | O2: 1.1612 | P2: 2500 | Q2: 2500.31 | R2: 2499.53 | S2: 2500.12 | T2: 2500.37 | U2: 2500.52 | V2: 2499.64 | W2: 2500.49 | X2: 209.8 | Y2: 2.01038 | Z2: 2.00818 | AA2: 2.00941 | AB2: 1.97917 | AC2: 2.01041 | AD2: 2.00644 | AE2: 2.011 | AF2: 2.0006 | AG2: 14.08.2026 23:19:20 | AH2: H2 | AI2: 41.172452 | AJ2: 37.76049 | AK2: 6706490 | AL2: 1.6183333 | AM2: 58.827548 | AN2: 53.952507 | AO2: 257479475 | AP2: 4 | AR2: =(AO2-5710532)/(4716081) -> 53.385203 | AS2: =(AK2-180057)/(179209) -> 36.417998 | AU2: =DATEVALUE(SUBSTITUTE(LEFT(A2,10),".","/")) -> 46248 | AV2: =TIMEVALUE(RIGHT(A2,8)) -> 0.90052083 | AW2: =DATEVALUE(SUBSTITUTE(LEFT(AG2,10),".","/")) -> 46248 | AX2: =TIMEVALUE(RIGHT(AG2,8)) -> 0.97175926 | AY2: 46248 | AZ2: 0.90053241 | BA2: R16_C1_S2_001_2026-08-14 21-0 | BB2: 0 | BC2: 0 | BD2: 0.117733 | BE2: 1.648836 | BF2: 0.549996 | BG2: 12.49423 | BH2: 7.563905 | BI2: 0 | BJ2: 17.33242 | BK2: 7.742486 | BL2: 3.727007 | BM2: 0.810594 | BN2: 0.03882 | BO2: 0.353294 | BP2: 0.667111 | BQ2: 0 | BR2: 15.871069 | BS2: 13.507695 | BT2: 1.329567 | BU2: 1.140245 | BV2: 0 | BW2: 13.552277 | BX2: 0.529629 | BY2: 0 | BZ2: 0.213448 | CA2: 0.031009 | CB2: 0 | CC2: 0 | CD2: 0.040806 | CE2: 0 | CF2: 0.039426 | CG2: 0 | CH2: 0 | CI2: 0.169391 | CJ2: 0.108001 | CK2: 0.421052 | CL2: 83.912094 | CM2: 16.14719 | CN2: 42.555553 | CO2: 41.119297 | CP2: 89.028351 | CQ2: 0.664206 | EH2: 88 | EK2: 50
A3: 14.08.2026 23:40:46 | B3: 2 | C3: 210 | D3: 210 | E3: 25.0246 | F3: 25.026 | G3: 1694.05 | H3: 1693.54 | I3: 1693.93 | J3: 1693.96 | K3: 1694.26 | L3: 1693.83 | M3: 1693.35 | N3: 1692.78 | O3: 1.18735 | P3: 2500.43 | Q3: 2500.11 | R3: 2499.22 | S3: 2499.81 | T3: 2499.6 | U3: 2499.46 | V3: 2499.5 | W3: 2500.32 | X3: 210.1 | Y3: 2.00509 | Z3: 2.00966 | AA3: 2.00857 | AB3: 2.02016 | AC3: 2.00788 | AD3: 2.01031 | AE3: 2.0118 | AF3: 2.00009 | AG3: 15.08.2026 01:23:22 | AH3: H2 | AI3: 39.392844 | AJ3: 35.565789 | AK3: 6316698 | AL3: 1.6183333 | AM3: 60.607156 | AN3: 54.719108 | AO3: 261137956 | AP3: 3.998 | AR3: =(AO3-5710532)/(4716081) -> 54.160949 | AS3: =(AK3-180057)/(179209) -> 34.242929 | AU3: =DATEVALUE(SUBSTITUTE(LEFT(A3,10),".","/")) -> 46248 | AV3: =TIMEVALUE(RIGHT(A3,8)) -> 0.98664352 | AW3: =DATEVALUE(SUBSTITUTE(LEFT(AG3,10),".","/")) -> 46249 | AX3: =TIMEVALUE(RIGHT(AG3,8)) -> 0.057893519 | AY3: 46248 | AZ3: 0.98666667 | BA3: R16_C1_S2_002_2026-08-14 23-1 | BB3: 0 | BC3: 0 | BD3: 0.964969 | BE3: 2.131811 | BF3: 2.8011 | BG3: 12.247929 | BH3: 8.297296 | BI3: 0 | BJ3: 15.944094 | BK3: 7.95385 | BL3: 4.285481 | BM3: 1.14805 | BN3: 0.125951 | BO3: 0.349556 | BP3: 0.666889 | BQ3: 0 | BR3: 11.79993 | BS3: 14.601999 | BT3: 2.717272 | BU3: 1.120726 | BV3: 0 | BW3: 9.749968 | BX3: 0.933777 | BY3: 0 | BZ3: 0.119804 | CA3: 0.012434 | CB3: 0 | CC3: 0 | CD3: 0.008718 | CE3: 0 | CF3: 0.027466 | CG3: 0 | CH3: 0 | CI3: 0.654126 | CJ3: 0.13954 | CK3: 1.196871 | CL3: 84.334549 | CM3: 15.998863 | CN3: 49.881214 | CO3: 47.755909 | CP3: 86.532341 | CQ3: 0.666729 | EH3: 88 | EK3: 50
